2024-11-17 19:13:01,046 - app - INFO - Loading model artifacts...
2024-11-17 19:13:01,594 - app - INFO - Model artifacts loaded successfully
2024-11-17 19:13:05,469 - app - ERROR - Exception on / [GET]
Traceback (most recent call last):
  File "/usr/local/python/3.12.1/lib/python3.12/site-packages/flask/app.py", line 2529, in wsgi_app
    response = self.full_dispatch_request()
               ^^^^^^^^^^^^^^^^^^^^^^^^^^^^
  File "/usr/local/python/3.12.1/lib/python3.12/site-packages/flask/app.py", line 1825, in full_dispatch_request
    rv = self.handle_user_exception(e)
         ^^^^^^^^^^^^^^^^^^^^^^^^^^^^^
  File "/usr/local/python/3.12.1/lib/python3.12/site-packages/flask/app.py", line 1823, in full_dispatch_request
    rv = self.dispatch_request()
         ^^^^^^^^^^^^^^^^^^^^^^^
  File "/usr/local/python/3.12.1/lib/python3.12/site-packages/flask/app.py", line 1799, in dispatch_request
    return self.ensure_sync(self.view_functions[rule.endpoint])(**view_args)
           ^^^^^^^^^^^^^^^^^^^^^^^^^^^^^^^^^^^^^^^^^^^^^^^^^^^^^^^^^^^^^^^^^
  File "/workspaces/happiness_prediction/app/app.py", line 90, in home
    return render_template('index.html', feature_names=feature_names)
           ^^^^^^^^^^^^^^^^^^^^^^^^^^^^^^^^^^^^^^^^^^^^^^^^^^^^^^^^^^
  File "/usr/local/python/3.12.1/lib/python3.12/site-packages/flask/templating.py", line 146, in render_template
    template = app.jinja_env.get_or_select_template(template_name_or_list)
               ^^^^^^^^^^^^^^^^^^^^^^^^^^^^^^^^^^^^^^^^^^^^^^^^^^^^^^^^^^^
  File "/home/codespace/.local/lib/python3.12/site-packages/jinja2/environment.py", line 1084, in get_or_select_template
    return self.get_template(template_name_or_list, parent, globals)
           ^^^^^^^^^^^^^^^^^^^^^^^^^^^^^^^^^^^^^^^^^^^^^^^^^^^^^^^^^
  File "/home/codespace/.local/lib/python3.12/site-packages/jinja2/environment.py", line 1013, in get_template
    return self._load_template(name, globals)
           ^^^^^^^^^^^^^^^^^^^^^^^^^^^^^^^^^^
  File "/home/codespace/.local/lib/python3.12/site-packages/jinja2/environment.py", line 972, in _load_template
    template = self.loader.load(self, name, self.make_globals(globals))
               ^^^^^^^^^^^^^^^^^^^^^^^^^^^^^^^^^^^^^^^^^^^^^^^^^^^^^^^^
  File "/home/codespace/.local/lib/python3.12/site-packages/jinja2/loaders.py", line 126, in load
    source, filename, uptodate = self.get_source(environment, name)
                                 ^^^^^^^^^^^^^^^^^^^^^^^^^^^^^^^^^^
  File "/usr/local/python/3.12.1/lib/python3.12/site-packages/flask/templating.py", line 62, in get_source
    return self._get_source_fast(environment, template)
           ^^^^^^^^^^^^^^^^^^^^^^^^^^^^^^^^^^^^^^^^^^^^
  File "/usr/local/python/3.12.1/lib/python3.12/site-packages/flask/templating.py", line 98, in _get_source_fast
    raise TemplateNotFound(template)
jinja2.exceptions.TemplateNotFound: index.html
2024-11-17 19:13:05,473 - app - ERROR - Server error: 500 Internal Server Error: The server encountered an internal error and was unable to complete your request. Either the server is overloaded or there is an error in the application.
2024-11-17 19:13:05,698 - app - ERROR - Exception on /favicon.ico [GET]
Traceback (most recent call last):
  File "/usr/local/python/3.12.1/lib/python3.12/site-packages/flask/app.py", line 1823, in full_dispatch_request
    rv = self.dispatch_request()
         ^^^^^^^^^^^^^^^^^^^^^^^
  File "/usr/local/python/3.12.1/lib/python3.12/site-packages/flask/app.py", line 1788, in dispatch_request
    self.raise_routing_exception(req)
  File "/usr/local/python/3.12.1/lib/python3.12/site-packages/flask/app.py", line 1770, in raise_routing_exception
    raise request.routing_exception  # type: ignore
    ^^^^^^^^^^^^^^^^^^^^^^^^^^^^^^^
  File "/usr/local/python/3.12.1/lib/python3.12/site-packages/flask/ctx.py", line 351, in match_request
    result = self.url_adapter.match(return_rule=True)  # type: ignore
             ^^^^^^^^^^^^^^^^^^^^^^^^^^^^^^^^^^^^^^^^
  File "/usr/local/python/3.12.1/lib/python3.12/site-packages/werkzeug/routing/map.py", line 624, in match
    raise NotFound() from None
werkzeug.exceptions.NotFound: 404 Not Found: The requested URL was not found on the server. If you entered the URL manually please check your spelling and try again.

During handling of the above exception, another exception occurred:

Traceback (most recent call last):
  File "/usr/local/python/3.12.1/lib/python3.12/site-packages/flask/app.py", line 2529, in wsgi_app
    response = self.full_dispatch_request()
               ^^^^^^^^^^^^^^^^^^^^^^^^^^^^
  File "/usr/local/python/3.12.1/lib/python3.12/site-packages/flask/app.py", line 1825, in full_dispatch_request
    rv = self.handle_user_exception(e)
         ^^^^^^^^^^^^^^^^^^^^^^^^^^^^^
  File "/usr/local/python/3.12.1/lib/python3.12/site-packages/flask/app.py", line 1669, in handle_user_exception
    return self.handle_http_exception(e)
           ^^^^^^^^^^^^^^^^^^^^^^^^^^^^^
  File "/usr/local/python/3.12.1/lib/python3.12/site-packages/flask/app.py", line 1609, in handle_http_exception
    return self.ensure_sync(handler)(e)
           ^^^^^^^^^^^^^^^^^^^^^^^^^^^^
  File "/workspaces/happiness_prediction/app/app.py", line 136, in not_found_error
    return render_template('error.html', error="Page not found"), 404
           ^^^^^^^^^^^^^^^^^^^^^^^^^^^^^^^^^^^^^^^^^^^^^^^^^^^^^
  File "/usr/local/python/3.12.1/lib/python3.12/site-packages/flask/templating.py", line 146, in render_template
    template = app.jinja_env.get_or_select_template(template_name_or_list)
               ^^^^^^^^^^^^^^^^^^^^^^^^^^^^^^^^^^^^^^^^^^^^^^^^^^^^^^^^^^^
  File "/home/codespace/.local/lib/python3.12/site-packages/jinja2/environment.py", line 1084, in get_or_select_template
    return self.get_template(template_name_or_list, parent, globals)
           ^^^^^^^^^^^^^^^^^^^^^^^^^^^^^^^^^^^^^^^^^^^^^^^^^^^^^^^^^
  File "/home/codespace/.local/lib/python3.12/site-packages/jinja2/environment.py", line 1013, in get_template
    return self._load_template(name, globals)
           ^^^^^^^^^^^^^^^^^^^^^^^^^^^^^^^^^^
  File "/home/codespace/.local/lib/python3.12/site-packages/jinja2/environment.py", line 972, in _load_template
    template = self.loader.load(self, name, self.make_globals(globals))
               ^^^^^^^^^^^^^^^^^^^^^^^^^^^^^^^^^^^^^^^^^^^^^^^^^^^^^^^^
  File "/home/codespace/.local/lib/python3.12/site-packages/jinja2/loaders.py", line 126, in load
    source, filename, uptodate = self.get_source(environment, name)
                                 ^^^^^^^^^^^^^^^^^^^^^^^^^^^^^^^^^^
  File "/usr/local/python/3.12.1/lib/python3.12/site-packages/flask/templating.py", line 62, in get_source
    return self._get_source_fast(environment, template)
           ^^^^^^^^^^^^^^^^^^^^^^^^^^^^^^^^^^^^^^^^^^^^
  File "/usr/local/python/3.12.1/lib/python3.12/site-packages/flask/templating.py", line 98, in _get_source_fast
    raise TemplateNotFound(template)
jinja2.exceptions.TemplateNotFound: error.html
2024-11-17 19:13:05,700 - app - ERROR - Server error: 500 Internal Server Error: The server encountered an internal error and was unable to complete your request. Either the server is overloaded or there is an error in the application.
2024-11-17 19:30:00,857 - app - INFO - Loading model artifacts...
2024-11-17 19:30:00,858 - app - INFO - Model path: /workspaces/happiness_prediction/models/best_model.pkl
2024-11-17 19:30:00,858 - app - INFO - Pipeline path: /workspaces/happiness_prediction/models/preprocessing_pipeline.pkl
2024-11-17 19:30:01,402 - app - INFO - Model artifacts loaded successfully
2024-11-17 19:30:01,402 - app - INFO - Loaded feature names: ['Economy (GDP per Capita)', 'Family', 'Health (Life Expectancy)', 'Freedom', 'Trust (Government Corruption)', 'Generosity']
2024-11-17 19:30:01,404 - app - INFO - Starting application on port 5000
2024-11-17 19:30:05,086 - app - ERROR - Exception on / [GET]
Traceback (most recent call last):
  File "/usr/local/python/3.12.1/lib/python3.12/site-packages/flask/app.py", line 2529, in wsgi_app
    response = self.full_dispatch_request()
               ^^^^^^^^^^^^^^^^^^^^^^^^^^^^
  File "/usr/local/python/3.12.1/lib/python3.12/site-packages/flask/app.py", line 1825, in full_dispatch_request
    rv = self.handle_user_exception(e)
         ^^^^^^^^^^^^^^^^^^^^^^^^^^^^^
  File "/usr/local/python/3.12.1/lib/python3.12/site-packages/flask_cors/extension.py", line 194, in wrapped_function
    return cors_after_request(app.make_response(f(*args, **kwargs)))
                                                ^^^^^^^^^^^^^^^^^^
  File "/usr/local/python/3.12.1/lib/python3.12/site-packages/flask/app.py", line 1823, in full_dispatch_request
    rv = self.dispatch_request()
         ^^^^^^^^^^^^^^^^^^^^^^^
  File "/usr/local/python/3.12.1/lib/python3.12/site-packages/flask/app.py", line 1799, in dispatch_request
    return self.ensure_sync(self.view_functions[rule.endpoint])(**view_args)
           ^^^^^^^^^^^^^^^^^^^^^^^^^^^^^^^^^^^^^^^^^^^^^^^^^^^^^^^^^^^^^^^^^
  File "/workspaces/happiness_prediction/app/app.py", line 133, in home
    return render_template('index.html',
          ^^^^^^^^^^^^^^^^^^^^^^^^^^^^^
  File "/usr/local/python/3.12.1/lib/python3.12/site-packages/flask/templating.py", line 146, in render_template
    template = app.jinja_env.get_or_select_template(template_name_or_list)
               ^^^^^^^^^^^^^^^^^^^^^^^^^^^^^^^^^^^^^^^^^^^^^^^^^^^^^^^^^^^
  File "/home/codespace/.local/lib/python3.12/site-packages/jinja2/environment.py", line 1084, in get_or_select_template
    return self.get_template(template_name_or_list, parent, globals)
           ^^^^^^^^^^^^^^^^^^^^^^^^^^^^^^^^^^^^^^^^^^^^^^^^^^^^^^^^^
  File "/home/codespace/.local/lib/python3.12/site-packages/jinja2/environment.py", line 1013, in get_template
    return self._load_template(name, globals)
           ^^^^^^^^^^^^^^^^^^^^^^^^^^^^^^^^^^
  File "/home/codespace/.local/lib/python3.12/site-packages/jinja2/environment.py", line 972, in _load_template
    template = self.loader.load(self, name, self.make_globals(globals))
               ^^^^^^^^^^^^^^^^^^^^^^^^^^^^^^^^^^^^^^^^^^^^^^^^^^^^^^^^
  File "/home/codespace/.local/lib/python3.12/site-packages/jinja2/loaders.py", line 126, in load
    source, filename, uptodate = self.get_source(environment, name)
                                 ^^^^^^^^^^^^^^^^^^^^^^^^^^^^^^^^^^
  File "/usr/local/python/3.12.1/lib/python3.12/site-packages/flask/templating.py", line 62, in get_source
    return self._get_source_fast(environment, template)
           ^^^^^^^^^^^^^^^^^^^^^^^^^^^^^^^^^^^^^^^^^^^^
  File "/usr/local/python/3.12.1/lib/python3.12/site-packages/flask/templating.py", line 98, in _get_source_fast
    raise TemplateNotFound(template)
jinja2.exceptions.TemplateNotFound: index.html
2024-11-17 19:30:05,091 - app - ERROR - Server error: 500 Internal Server Error: The server encountered an internal error and was unable to complete your request. Either the server is overloaded or there is an error in the application.
Traceback (most recent call last):
  File "/usr/local/python/3.12.1/lib/python3.12/site-packages/flask/app.py", line 2529, in wsgi_app
    response = self.full_dispatch_request()
               ^^^^^^^^^^^^^^^^^^^^^^^^^^^^
  File "/usr/local/python/3.12.1/lib/python3.12/site-packages/flask/app.py", line 1825, in full_dispatch_request
    rv = self.handle_user_exception(e)
         ^^^^^^^^^^^^^^^^^^^^^^^^^^^^^
  File "/usr/local/python/3.12.1/lib/python3.12/site-packages/flask_cors/extension.py", line 194, in wrapped_function
    return cors_after_request(app.make_response(f(*args, **kwargs)))
                                                ^^^^^^^^^^^^^^^^^^
  File "/usr/local/python/3.12.1/lib/python3.12/site-packages/flask/app.py", line 1823, in full_dispatch_request
    rv = self.dispatch_request()
         ^^^^^^^^^^^^^^^^^^^^^^^
  File "/usr/local/python/3.12.1/lib/python3.12/site-packages/flask/app.py", line 1799, in dispatch_request
    return self.ensure_sync(self.view_functions[rule.endpoint])(**view_args)
           ^^^^^^^^^^^^^^^^^^^^^^^^^^^^^^^^^^^^^^^^^^^^^^^^^^^^^^^^^^^^^^^^^
  File "/workspaces/happiness_prediction/app/app.py", line 133, in home
    return render_template('index.html',
          ^^^^^^^^^^^^^^^^^^^^^^^^^^^^^
  File "/usr/local/python/3.12.1/lib/python3.12/site-packages/flask/templating.py", line 146, in render_template
    template = app.jinja_env.get_or_select_template(template_name_or_list)
               ^^^^^^^^^^^^^^^^^^^^^^^^^^^^^^^^^^^^^^^^^^^^^^^^^^^^^^^^^^^
  File "/home/codespace/.local/lib/python3.12/site-packages/jinja2/environment.py", line 1084, in get_or_select_template
    return self.get_template(template_name_or_list, parent, globals)
           ^^^^^^^^^^^^^^^^^^^^^^^^^^^^^^^^^^^^^^^^^^^^^^^^^^^^^^^^^
  File "/home/codespace/.local/lib/python3.12/site-packages/jinja2/environment.py", line 1013, in get_template
    return self._load_template(name, globals)
           ^^^^^^^^^^^^^^^^^^^^^^^^^^^^^^^^^^
  File "/home/codespace/.local/lib/python3.12/site-packages/jinja2/environment.py", line 972, in _load_template
    template = self.loader.load(self, name, self.make_globals(globals))
               ^^^^^^^^^^^^^^^^^^^^^^^^^^^^^^^^^^^^^^^^^^^^^^^^^^^^^^^^
  File "/home/codespace/.local/lib/python3.12/site-packages/jinja2/loaders.py", line 126, in load
    source, filename, uptodate = self.get_source(environment, name)
                                 ^^^^^^^^^^^^^^^^^^^^^^^^^^^^^^^^^^
  File "/usr/local/python/3.12.1/lib/python3.12/site-packages/flask/templating.py", line 62, in get_source
    return self._get_source_fast(environment, template)
           ^^^^^^^^^^^^^^^^^^^^^^^^^^^^^^^^^^^^^^^^^^^^
  File "/usr/local/python/3.12.1/lib/python3.12/site-packages/flask/templating.py", line 98, in _get_source_fast
    raise TemplateNotFound(template)
jinja2.exceptions.TemplateNotFound: index.html

2024-11-17 19:30:05,272 - app - ERROR - Exception on /favicon.ico [GET]
Traceback (most recent call last):
  File "/usr/local/python/3.12.1/lib/python3.12/site-packages/flask/app.py", line 1823, in full_dispatch_request
    rv = self.dispatch_request()
         ^^^^^^^^^^^^^^^^^^^^^^^
  File "/usr/local/python/3.12.1/lib/python3.12/site-packages/flask/app.py", line 1788, in dispatch_request
    self.raise_routing_exception(req)
  File "/usr/local/python/3.12.1/lib/python3.12/site-packages/flask/app.py", line 1770, in raise_routing_exception
    raise request.routing_exception  # type: ignore
    ^^^^^^^^^^^^^^^^^^^^^^^^^^^^^^^
  File "/usr/local/python/3.12.1/lib/python3.12/site-packages/flask/ctx.py", line 351, in match_request
    result = self.url_adapter.match(return_rule=True)  # type: ignore
             ^^^^^^^^^^^^^^^^^^^^^^^^^^^^^^^^^^^^^^^^
  File "/usr/local/python/3.12.1/lib/python3.12/site-packages/werkzeug/routing/map.py", line 624, in match
    raise NotFound() from None
werkzeug.exceptions.NotFound: 404 Not Found: The requested URL was not found on the server. If you entered the URL manually please check your spelling and try again.

During handling of the above exception, another exception occurred:

Traceback (most recent call last):
  File "/usr/local/python/3.12.1/lib/python3.12/site-packages/flask/app.py", line 2529, in wsgi_app
    response = self.full_dispatch_request()
               ^^^^^^^^^^^^^^^^^^^^^^^^^^^^
  File "/usr/local/python/3.12.1/lib/python3.12/site-packages/flask/app.py", line 1825, in full_dispatch_request
    rv = self.handle_user_exception(e)
         ^^^^^^^^^^^^^^^^^^^^^^^^^^^^^
  File "/usr/local/python/3.12.1/lib/python3.12/site-packages/flask_cors/extension.py", line 194, in wrapped_function
    return cors_after_request(app.make_response(f(*args, **kwargs)))
                                                ^^^^^^^^^^^^^^^^^^
  File "/usr/local/python/3.12.1/lib/python3.12/site-packages/flask/app.py", line 1669, in handle_user_exception
    return self.handle_http_exception(e)
           ^^^^^^^^^^^^^^^^^^^^^^^^^^^^^
  File "/usr/local/python/3.12.1/lib/python3.12/site-packages/flask/app.py", line 1609, in handle_http_exception
    return self.ensure_sync(handler)(e)
           ^^^^^^^^^^^^^^^^^^^^^^^^^^^^
  File "/workspaces/happiness_prediction/app/app.py", line 205, in not_found_error
    return render_template('error.html',
          ^^^^^^^^^^^^^^^^^^^^^^^^^^^^^
  File "/usr/local/python/3.12.1/lib/python3.12/site-packages/flask/templating.py", line 146, in render_template
    template = app.jinja_env.get_or_select_template(template_name_or_list)
               ^^^^^^^^^^^^^^^^^^^^^^^^^^^^^^^^^^^^^^^^^^^^^^^^^^^^^^^^^^^
  File "/home/codespace/.local/lib/python3.12/site-packages/jinja2/environment.py", line 1084, in get_or_select_template
    return self.get_template(template_name_or_list, parent, globals)
           ^^^^^^^^^^^^^^^^^^^^^^^^^^^^^^^^^^^^^^^^^^^^^^^^^^^^^^^^^
  File "/home/codespace/.local/lib/python3.12/site-packages/jinja2/environment.py", line 1013, in get_template
    return self._load_template(name, globals)
           ^^^^^^^^^^^^^^^^^^^^^^^^^^^^^^^^^^
  File "/home/codespace/.local/lib/python3.12/site-packages/jinja2/environment.py", line 972, in _load_template
    template = self.loader.load(self, name, self.make_globals(globals))
               ^^^^^^^^^^^^^^^^^^^^^^^^^^^^^^^^^^^^^^^^^^^^^^^^^^^^^^^^
  File "/home/codespace/.local/lib/python3.12/site-packages/jinja2/loaders.py", line 126, in load
    source, filename, uptodate = self.get_source(environment, name)
                                 ^^^^^^^^^^^^^^^^^^^^^^^^^^^^^^^^^^
  File "/usr/local/python/3.12.1/lib/python3.12/site-packages/flask/templating.py", line 62, in get_source
    return self._get_source_fast(environment, template)
           ^^^^^^^^^^^^^^^^^^^^^^^^^^^^^^^^^^^^^^^^^^^^
  File "/usr/local/python/3.12.1/lib/python3.12/site-packages/flask/templating.py", line 98, in _get_source_fast
    raise TemplateNotFound(template)
jinja2.exceptions.TemplateNotFound: error.html
2024-11-17 19:30:05,275 - app - ERROR - Server error: 500 Internal Server Error: The server encountered an internal error and was unable to complete your request. Either the server is overloaded or there is an error in the application.
Traceback (most recent call last):
  File "/usr/local/python/3.12.1/lib/python3.12/site-packages/flask/app.py", line 1823, in full_dispatch_request
    rv = self.dispatch_request()
         ^^^^^^^^^^^^^^^^^^^^^^^
  File "/usr/local/python/3.12.1/lib/python3.12/site-packages/flask/app.py", line 1788, in dispatch_request
    self.raise_routing_exception(req)
  File "/usr/local/python/3.12.1/lib/python3.12/site-packages/flask/app.py", line 1770, in raise_routing_exception
    raise request.routing_exception  # type: ignore
    ^^^^^^^^^^^^^^^^^^^^^^^^^^^^^^^
  File "/usr/local/python/3.12.1/lib/python3.12/site-packages/flask/ctx.py", line 351, in match_request
    result = self.url_adapter.match(return_rule=True)  # type: ignore
             ^^^^^^^^^^^^^^^^^^^^^^^^^^^^^^^^^^^^^^^^
  File "/usr/local/python/3.12.1/lib/python3.12/site-packages/werkzeug/routing/map.py", line 624, in match
    raise NotFound() from None
werkzeug.exceptions.NotFound: 404 Not Found: The requested URL was not found on the server. If you entered the URL manually please check your spelling and try again.

During handling of the above exception, another exception occurred:

Traceback (most recent call last):
  File "/usr/local/python/3.12.1/lib/python3.12/site-packages/flask/app.py", line 2529, in wsgi_app
    response = self.full_dispatch_request()
               ^^^^^^^^^^^^^^^^^^^^^^^^^^^^
  File "/usr/local/python/3.12.1/lib/python3.12/site-packages/flask/app.py", line 1825, in full_dispatch_request
    rv = self.handle_user_exception(e)
         ^^^^^^^^^^^^^^^^^^^^^^^^^^^^^
  File "/usr/local/python/3.12.1/lib/python3.12/site-packages/flask_cors/extension.py", line 194, in wrapped_function
    return cors_after_request(app.make_response(f(*args, **kwargs)))
                                                ^^^^^^^^^^^^^^^^^^
  File "/usr/local/python/3.12.1/lib/python3.12/site-packages/flask/app.py", line 1669, in handle_user_exception
    return self.handle_http_exception(e)
           ^^^^^^^^^^^^^^^^^^^^^^^^^^^^^
  File "/usr/local/python/3.12.1/lib/python3.12/site-packages/flask/app.py", line 1609, in handle_http_exception
    return self.ensure_sync(handler)(e)
           ^^^^^^^^^^^^^^^^^^^^^^^^^^^^
  File "/workspaces/happiness_prediction/app/app.py", line 205, in not_found_error
    return render_template('error.html',
          ^^^^^^^^^^^^^^^^^^^^^^^^^^^^^
  File "/usr/local/python/3.12.1/lib/python3.12/site-packages/flask/templating.py", line 146, in render_template
    template = app.jinja_env.get_or_select_template(template_name_or_list)
               ^^^^^^^^^^^^^^^^^^^^^^^^^^^^^^^^^^^^^^^^^^^^^^^^^^^^^^^^^^^
  File "/home/codespace/.local/lib/python3.12/site-packages/jinja2/environment.py", line 1084, in get_or_select_template
    return self.get_template(template_name_or_list, parent, globals)
           ^^^^^^^^^^^^^^^^^^^^^^^^^^^^^^^^^^^^^^^^^^^^^^^^^^^^^^^^^
  File "/home/codespace/.local/lib/python3.12/site-packages/jinja2/environment.py", line 1013, in get_template
    return self._load_template(name, globals)
           ^^^^^^^^^^^^^^^^^^^^^^^^^^^^^^^^^^
  File "/home/codespace/.local/lib/python3.12/site-packages/jinja2/environment.py", line 972, in _load_template
    template = self.loader.load(self, name, self.make_globals(globals))
               ^^^^^^^^^^^^^^^^^^^^^^^^^^^^^^^^^^^^^^^^^^^^^^^^^^^^^^^^
  File "/home/codespace/.local/lib/python3.12/site-packages/jinja2/loaders.py", line 126, in load
    source, filename, uptodate = self.get_source(environment, name)
                                 ^^^^^^^^^^^^^^^^^^^^^^^^^^^^^^^^^^
  File "/usr/local/python/3.12.1/lib/python3.12/site-packages/flask/templating.py", line 62, in get_source
    return self._get_source_fast(environment, template)
           ^^^^^^^^^^^^^^^^^^^^^^^^^^^^^^^^^^^^^^^^^^^^
  File "/usr/local/python/3.12.1/lib/python3.12/site-packages/flask/templating.py", line 98, in _get_source_fast
    raise TemplateNotFound(template)
jinja2.exceptions.TemplateNotFound: error.html

2024-11-17 19:33:40,132 - app - INFO - Loading model artifacts...
2024-11-17 19:33:40,132 - app - INFO - Model path: /workspaces/happiness_prediction/models/best_model.pkl
2024-11-17 19:33:40,132 - app - INFO - Pipeline path: /workspaces/happiness_prediction/models/preprocessing_pipeline.pkl
2024-11-17 19:33:40,591 - app - INFO - Model artifacts loaded successfully
2024-11-17 19:33:40,591 - app - INFO - Loaded feature names: ['Economy (GDP per Capita)', 'Family', 'Health (Life Expectancy)', 'Freedom', 'Trust (Government Corruption)', 'Generosity']
2024-11-17 19:33:40,593 - app - INFO - Starting application on port 5000
2024-11-17 19:33:43,716 - app - INFO - 127.0.0.1 GET http /? 200 OK
2024-11-17 19:33:43,757 - app - INFO - 127.0.0.1 GET http /static/css/style.css? 200 OK
2024-11-17 19:33:43,769 - app - INFO - 127.0.0.1 GET http /static/js/main.js? 200 OK
2024-11-17 19:33:44,499 - app - ERROR - Exception on /favicon.ico [GET]
Traceback (most recent call last):
  File "/usr/local/python/3.12.1/lib/python3.12/site-packages/flask/app.py", line 1823, in full_dispatch_request
    rv = self.dispatch_request()
         ^^^^^^^^^^^^^^^^^^^^^^^
  File "/usr/local/python/3.12.1/lib/python3.12/site-packages/flask/app.py", line 1788, in dispatch_request
    self.raise_routing_exception(req)
  File "/usr/local/python/3.12.1/lib/python3.12/site-packages/flask/app.py", line 1770, in raise_routing_exception
    raise request.routing_exception  # type: ignore
    ^^^^^^^^^^^^^^^^^^^^^^^^^^^^^^^
  File "/usr/local/python/3.12.1/lib/python3.12/site-packages/flask/ctx.py", line 351, in match_request
    result = self.url_adapter.match(return_rule=True)  # type: ignore
             ^^^^^^^^^^^^^^^^^^^^^^^^^^^^^^^^^^^^^^^^
  File "/usr/local/python/3.12.1/lib/python3.12/site-packages/werkzeug/routing/map.py", line 624, in match
    raise NotFound() from None
werkzeug.exceptions.NotFound: 404 Not Found: The requested URL was not found on the server. If you entered the URL manually please check your spelling and try again.

During handling of the above exception, another exception occurred:

Traceback (most recent call last):
  File "/usr/local/python/3.12.1/lib/python3.12/site-packages/flask/app.py", line 2529, in wsgi_app
    response = self.full_dispatch_request()
               ^^^^^^^^^^^^^^^^^^^^^^^^^^^^
  File "/usr/local/python/3.12.1/lib/python3.12/site-packages/flask/app.py", line 1825, in full_dispatch_request
    rv = self.handle_user_exception(e)
         ^^^^^^^^^^^^^^^^^^^^^^^^^^^^^
  File "/usr/local/python/3.12.1/lib/python3.12/site-packages/flask_cors/extension.py", line 194, in wrapped_function
    return cors_after_request(app.make_response(f(*args, **kwargs)))
                                                ^^^^^^^^^^^^^^^^^^
  File "/usr/local/python/3.12.1/lib/python3.12/site-packages/flask/app.py", line 1669, in handle_user_exception
    return self.handle_http_exception(e)
           ^^^^^^^^^^^^^^^^^^^^^^^^^^^^^
  File "/usr/local/python/3.12.1/lib/python3.12/site-packages/flask/app.py", line 1609, in handle_http_exception
    return self.ensure_sync(handler)(e)
           ^^^^^^^^^^^^^^^^^^^^^^^^^^^^
  File "/workspaces/happiness_prediction/app/app.py", line 205, in not_found_error
    return render_template('error.html',
          ^^^^^^^^^^^^^^^^^^^^^^^^^^^^^
  File "/usr/local/python/3.12.1/lib/python3.12/site-packages/flask/templating.py", line 146, in render_template
    template = app.jinja_env.get_or_select_template(template_name_or_list)
               ^^^^^^^^^^^^^^^^^^^^^^^^^^^^^^^^^^^^^^^^^^^^^^^^^^^^^^^^^^^
  File "/home/codespace/.local/lib/python3.12/site-packages/jinja2/environment.py", line 1084, in get_or_select_template
    return self.get_template(template_name_or_list, parent, globals)
           ^^^^^^^^^^^^^^^^^^^^^^^^^^^^^^^^^^^^^^^^^^^^^^^^^^^^^^^^^
  File "/home/codespace/.local/lib/python3.12/site-packages/jinja2/environment.py", line 1013, in get_template
    return self._load_template(name, globals)
           ^^^^^^^^^^^^^^^^^^^^^^^^^^^^^^^^^^
  File "/home/codespace/.local/lib/python3.12/site-packages/jinja2/environment.py", line 972, in _load_template
    template = self.loader.load(self, name, self.make_globals(globals))
               ^^^^^^^^^^^^^^^^^^^^^^^^^^^^^^^^^^^^^^^^^^^^^^^^^^^^^^^^
  File "/home/codespace/.local/lib/python3.12/site-packages/jinja2/loaders.py", line 126, in load
    source, filename, uptodate = self.get_source(environment, name)
                                 ^^^^^^^^^^^^^^^^^^^^^^^^^^^^^^^^^^
  File "/usr/local/python/3.12.1/lib/python3.12/site-packages/flask/templating.py", line 62, in get_source
    return self._get_source_fast(environment, template)
           ^^^^^^^^^^^^^^^^^^^^^^^^^^^^^^^^^^^^^^^^^^^^
  File "/usr/local/python/3.12.1/lib/python3.12/site-packages/flask/templating.py", line 98, in _get_source_fast
    raise TemplateNotFound(template)
jinja2.exceptions.TemplateNotFound: error.html
2024-11-17 19:33:44,502 - app - ERROR - Server error: 500 Internal Server Error: The server encountered an internal error and was unable to complete your request. Either the server is overloaded or there is an error in the application.
Traceback (most recent call last):
  File "/usr/local/python/3.12.1/lib/python3.12/site-packages/flask/app.py", line 1823, in full_dispatch_request
    rv = self.dispatch_request()
         ^^^^^^^^^^^^^^^^^^^^^^^
  File "/usr/local/python/3.12.1/lib/python3.12/site-packages/flask/app.py", line 1788, in dispatch_request
    self.raise_routing_exception(req)
  File "/usr/local/python/3.12.1/lib/python3.12/site-packages/flask/app.py", line 1770, in raise_routing_exception
    raise request.routing_exception  # type: ignore
    ^^^^^^^^^^^^^^^^^^^^^^^^^^^^^^^
  File "/usr/local/python/3.12.1/lib/python3.12/site-packages/flask/ctx.py", line 351, in match_request
    result = self.url_adapter.match(return_rule=True)  # type: ignore
             ^^^^^^^^^^^^^^^^^^^^^^^^^^^^^^^^^^^^^^^^
  File "/usr/local/python/3.12.1/lib/python3.12/site-packages/werkzeug/routing/map.py", line 624, in match
    raise NotFound() from None
werkzeug.exceptions.NotFound: 404 Not Found: The requested URL was not found on the server. If you entered the URL manually please check your spelling and try again.

During handling of the above exception, another exception occurred:

Traceback (most recent call last):
  File "/usr/local/python/3.12.1/lib/python3.12/site-packages/flask/app.py", line 2529, in wsgi_app
    response = self.full_dispatch_request()
               ^^^^^^^^^^^^^^^^^^^^^^^^^^^^
  File "/usr/local/python/3.12.1/lib/python3.12/site-packages/flask/app.py", line 1825, in full_dispatch_request
    rv = self.handle_user_exception(e)
         ^^^^^^^^^^^^^^^^^^^^^^^^^^^^^
  File "/usr/local/python/3.12.1/lib/python3.12/site-packages/flask_cors/extension.py", line 194, in wrapped_function
    return cors_after_request(app.make_response(f(*args, **kwargs)))
                                                ^^^^^^^^^^^^^^^^^^
  File "/usr/local/python/3.12.1/lib/python3.12/site-packages/flask/app.py", line 1669, in handle_user_exception
    return self.handle_http_exception(e)
           ^^^^^^^^^^^^^^^^^^^^^^^^^^^^^
  File "/usr/local/python/3.12.1/lib/python3.12/site-packages/flask/app.py", line 1609, in handle_http_exception
    return self.ensure_sync(handler)(e)
           ^^^^^^^^^^^^^^^^^^^^^^^^^^^^
  File "/workspaces/happiness_prediction/app/app.py", line 205, in not_found_error
    return render_template('error.html',
          ^^^^^^^^^^^^^^^^^^^^^^^^^^^^^
  File "/usr/local/python/3.12.1/lib/python3.12/site-packages/flask/templating.py", line 146, in render_template
    template = app.jinja_env.get_or_select_template(template_name_or_list)
               ^^^^^^^^^^^^^^^^^^^^^^^^^^^^^^^^^^^^^^^^^^^^^^^^^^^^^^^^^^^
  File "/home/codespace/.local/lib/python3.12/site-packages/jinja2/environment.py", line 1084, in get_or_select_template
    return self.get_template(template_name_or_list, parent, globals)
           ^^^^^^^^^^^^^^^^^^^^^^^^^^^^^^^^^^^^^^^^^^^^^^^^^^^^^^^^^
  File "/home/codespace/.local/lib/python3.12/site-packages/jinja2/environment.py", line 1013, in get_template
    return self._load_template(name, globals)
           ^^^^^^^^^^^^^^^^^^^^^^^^^^^^^^^^^^
  File "/home/codespace/.local/lib/python3.12/site-packages/jinja2/environment.py", line 972, in _load_template
    template = self.loader.load(self, name, self.make_globals(globals))
               ^^^^^^^^^^^^^^^^^^^^^^^^^^^^^^^^^^^^^^^^^^^^^^^^^^^^^^^^
  File "/home/codespace/.local/lib/python3.12/site-packages/jinja2/loaders.py", line 126, in load
    source, filename, uptodate = self.get_source(environment, name)
                                 ^^^^^^^^^^^^^^^^^^^^^^^^^^^^^^^^^^
  File "/usr/local/python/3.12.1/lib/python3.12/site-packages/flask/templating.py", line 62, in get_source
    return self._get_source_fast(environment, template)
           ^^^^^^^^^^^^^^^^^^^^^^^^^^^^^^^^^^^^^^^^^^^^
  File "/usr/local/python/3.12.1/lib/python3.12/site-packages/flask/templating.py", line 98, in _get_source_fast
    raise TemplateNotFound(template)
jinja2.exceptions.TemplateNotFound: error.html

2024-11-17 19:34:30,953 - app - INFO - Prediction log: {'timestamp': '2024-11-17T19:34:30.953782', 'input_data': {'Economy (GDP per Capita)': 0.03, 'Family': 0.03, 'Health (Life Expectancy)': 0.04, 'Freedom': 0.05, 'Trust (Government Corruption)': 0.04, 'Generosity': 0.04}, 'prediction': None, 'success': False, 'error': "'dict' object has no attribute 'transform'", 'client_ip': '127.0.0.1'}
2024-11-17 19:34:30,955 - app - ERROR - Prediction error: 'dict' object has no attribute 'transform'
Traceback (most recent call last):
  File "/workspaces/happiness_prediction/app/app.py", line 159, in predict
    processed_data = pipeline.transform(input_df)
                     ^^^^^^^^^^^^^^^^^^
AttributeError: 'dict' object has no attribute 'transform'

2024-11-17 19:34:30,955 - app - INFO - 127.0.0.1 POST http /predict? 400 BAD REQUEST
2024-11-17 19:57:58,381 - app - INFO - Loading model artifacts...
2024-11-17 19:57:58,533 - app - INFO - Model artifacts loaded successfully
2024-11-17 19:57:58,533 - app - INFO - Model type: <class 'sklearn.ensemble._forest.RandomForestRegressor'>
2024-11-17 19:57:58,533 - app - INFO - Pipeline type: <class 'preprocessing_pipeline.PreprocessingPipeline'>
2024-11-17 19:57:58,533 - app - INFO - Loaded feature names: ['Economy (GDP per Capita)', 'Family', 'Health (Life Expectancy)', 'Freedom', 'Trust (Government Corruption)', 'Generosity']
2024-11-17 19:57:58,535 - app - INFO - Starting application on port 5000
2024-11-17 19:58:02,574 - app - ERROR - Exception on /favicon.ico [GET]
Traceback (most recent call last):
  File "/usr/local/python/3.12.1/lib/python3.12/site-packages/flask/app.py", line 1823, in full_dispatch_request
    rv = self.dispatch_request()
         ^^^^^^^^^^^^^^^^^^^^^^^
  File "/usr/local/python/3.12.1/lib/python3.12/site-packages/flask/app.py", line 1788, in dispatch_request
    self.raise_routing_exception(req)
  File "/usr/local/python/3.12.1/lib/python3.12/site-packages/flask/app.py", line 1770, in raise_routing_exception
    raise request.routing_exception  # type: ignore
    ^^^^^^^^^^^^^^^^^^^^^^^^^^^^^^^
  File "/usr/local/python/3.12.1/lib/python3.12/site-packages/flask/ctx.py", line 351, in match_request
    result = self.url_adapter.match(return_rule=True)  # type: ignore
             ^^^^^^^^^^^^^^^^^^^^^^^^^^^^^^^^^^^^^^^^
  File "/usr/local/python/3.12.1/lib/python3.12/site-packages/werkzeug/routing/map.py", line 624, in match
    raise NotFound() from None
werkzeug.exceptions.NotFound: 404 Not Found: The requested URL was not found on the server. If you entered the URL manually please check your spelling and try again.

During handling of the above exception, another exception occurred:

Traceback (most recent call last):
  File "/usr/local/python/3.12.1/lib/python3.12/site-packages/flask/app.py", line 2529, in wsgi_app
    response = self.full_dispatch_request()
               ^^^^^^^^^^^^^^^^^^^^^^^^^^^^
  File "/usr/local/python/3.12.1/lib/python3.12/site-packages/flask/app.py", line 1825, in full_dispatch_request
    rv = self.handle_user_exception(e)
         ^^^^^^^^^^^^^^^^^^^^^^^^^^^^^
  File "/usr/local/python/3.12.1/lib/python3.12/site-packages/flask_cors/extension.py", line 194, in wrapped_function
    return cors_after_request(app.make_response(f(*args, **kwargs)))
                                                ^^^^^^^^^^^^^^^^^^
  File "/usr/local/python/3.12.1/lib/python3.12/site-packages/flask/app.py", line 1669, in handle_user_exception
    return self.handle_http_exception(e)
           ^^^^^^^^^^^^^^^^^^^^^^^^^^^^^
  File "/usr/local/python/3.12.1/lib/python3.12/site-packages/flask/app.py", line 1609, in handle_http_exception
    return self.ensure_sync(handler)(e)
           ^^^^^^^^^^^^^^^^^^^^^^^^^^^^
  File "/workspaces/happiness_prediction/app/app.py", line 207, in not_found_error
    return render_template('error.html',
          ^^^^^^^^^^^^^^^^^^^^^^^^^^^^^
  File "/usr/local/python/3.12.1/lib/python3.12/site-packages/flask/templating.py", line 146, in render_template
    template = app.jinja_env.get_or_select_template(template_name_or_list)
               ^^^^^^^^^^^^^^^^^^^^^^^^^^^^^^^^^^^^^^^^^^^^^^^^^^^^^^^^^^^
  File "/home/codespace/.local/lib/python3.12/site-packages/jinja2/environment.py", line 1084, in get_or_select_template
    return self.get_template(template_name_or_list, parent, globals)
           ^^^^^^^^^^^^^^^^^^^^^^^^^^^^^^^^^^^^^^^^^^^^^^^^^^^^^^^^^
  File "/home/codespace/.local/lib/python3.12/site-packages/jinja2/environment.py", line 1013, in get_template
    return self._load_template(name, globals)
           ^^^^^^^^^^^^^^^^^^^^^^^^^^^^^^^^^^
  File "/home/codespace/.local/lib/python3.12/site-packages/jinja2/environment.py", line 972, in _load_template
    template = self.loader.load(self, name, self.make_globals(globals))
               ^^^^^^^^^^^^^^^^^^^^^^^^^^^^^^^^^^^^^^^^^^^^^^^^^^^^^^^^
  File "/home/codespace/.local/lib/python3.12/site-packages/jinja2/loaders.py", line 126, in load
    source, filename, uptodate = self.get_source(environment, name)
                                 ^^^^^^^^^^^^^^^^^^^^^^^^^^^^^^^^^^
  File "/usr/local/python/3.12.1/lib/python3.12/site-packages/flask/templating.py", line 62, in get_source
    return self._get_source_fast(environment, template)
           ^^^^^^^^^^^^^^^^^^^^^^^^^^^^^^^^^^^^^^^^^^^^
  File "/usr/local/python/3.12.1/lib/python3.12/site-packages/flask/templating.py", line 98, in _get_source_fast
    raise TemplateNotFound(template)
jinja2.exceptions.TemplateNotFound: error.html
2024-11-17 19:58:02,577 - app - ERROR - Server error: 500 Internal Server Error: The server encountered an internal error and was unable to complete your request. Either the server is overloaded or there is an error in the application.
Traceback (most recent call last):
  File "/usr/local/python/3.12.1/lib/python3.12/site-packages/flask/app.py", line 1823, in full_dispatch_request
    rv = self.dispatch_request()
         ^^^^^^^^^^^^^^^^^^^^^^^
  File "/usr/local/python/3.12.1/lib/python3.12/site-packages/flask/app.py", line 1788, in dispatch_request
    self.raise_routing_exception(req)
  File "/usr/local/python/3.12.1/lib/python3.12/site-packages/flask/app.py", line 1770, in raise_routing_exception
    raise request.routing_exception  # type: ignore
    ^^^^^^^^^^^^^^^^^^^^^^^^^^^^^^^
  File "/usr/local/python/3.12.1/lib/python3.12/site-packages/flask/ctx.py", line 351, in match_request
    result = self.url_adapter.match(return_rule=True)  # type: ignore
             ^^^^^^^^^^^^^^^^^^^^^^^^^^^^^^^^^^^^^^^^
  File "/usr/local/python/3.12.1/lib/python3.12/site-packages/werkzeug/routing/map.py", line 624, in match
    raise NotFound() from None
werkzeug.exceptions.NotFound: 404 Not Found: The requested URL was not found on the server. If you entered the URL manually please check your spelling and try again.

During handling of the above exception, another exception occurred:

Traceback (most recent call last):
  File "/usr/local/python/3.12.1/lib/python3.12/site-packages/flask/app.py", line 2529, in wsgi_app
    response = self.full_dispatch_request()
               ^^^^^^^^^^^^^^^^^^^^^^^^^^^^
  File "/usr/local/python/3.12.1/lib/python3.12/site-packages/flask/app.py", line 1825, in full_dispatch_request
    rv = self.handle_user_exception(e)
         ^^^^^^^^^^^^^^^^^^^^^^^^^^^^^
  File "/usr/local/python/3.12.1/lib/python3.12/site-packages/flask_cors/extension.py", line 194, in wrapped_function
    return cors_after_request(app.make_response(f(*args, **kwargs)))
                                                ^^^^^^^^^^^^^^^^^^
  File "/usr/local/python/3.12.1/lib/python3.12/site-packages/flask/app.py", line 1669, in handle_user_exception
    return self.handle_http_exception(e)
           ^^^^^^^^^^^^^^^^^^^^^^^^^^^^^
  File "/usr/local/python/3.12.1/lib/python3.12/site-packages/flask/app.py", line 1609, in handle_http_exception
    return self.ensure_sync(handler)(e)
           ^^^^^^^^^^^^^^^^^^^^^^^^^^^^
  File "/workspaces/happiness_prediction/app/app.py", line 207, in not_found_error
    return render_template('error.html',
          ^^^^^^^^^^^^^^^^^^^^^^^^^^^^^
  File "/usr/local/python/3.12.1/lib/python3.12/site-packages/flask/templating.py", line 146, in render_template
    template = app.jinja_env.get_or_select_template(template_name_or_list)
               ^^^^^^^^^^^^^^^^^^^^^^^^^^^^^^^^^^^^^^^^^^^^^^^^^^^^^^^^^^^
  File "/home/codespace/.local/lib/python3.12/site-packages/jinja2/environment.py", line 1084, in get_or_select_template
    return self.get_template(template_name_or_list, parent, globals)
           ^^^^^^^^^^^^^^^^^^^^^^^^^^^^^^^^^^^^^^^^^^^^^^^^^^^^^^^^^
  File "/home/codespace/.local/lib/python3.12/site-packages/jinja2/environment.py", line 1013, in get_template
    return self._load_template(name, globals)
           ^^^^^^^^^^^^^^^^^^^^^^^^^^^^^^^^^^
  File "/home/codespace/.local/lib/python3.12/site-packages/jinja2/environment.py", line 972, in _load_template
    template = self.loader.load(self, name, self.make_globals(globals))
               ^^^^^^^^^^^^^^^^^^^^^^^^^^^^^^^^^^^^^^^^^^^^^^^^^^^^^^^^
  File "/home/codespace/.local/lib/python3.12/site-packages/jinja2/loaders.py", line 126, in load
    source, filename, uptodate = self.get_source(environment, name)
                                 ^^^^^^^^^^^^^^^^^^^^^^^^^^^^^^^^^^
  File "/usr/local/python/3.12.1/lib/python3.12/site-packages/flask/templating.py", line 62, in get_source
    return self._get_source_fast(environment, template)
           ^^^^^^^^^^^^^^^^^^^^^^^^^^^^^^^^^^^^^^^^^^^^
  File "/usr/local/python/3.12.1/lib/python3.12/site-packages/flask/templating.py", line 98, in _get_source_fast
    raise TemplateNotFound(template)
jinja2.exceptions.TemplateNotFound: error.html

2024-11-17 19:58:18,961 - app - INFO - Input data shape: (1, 6)
2024-11-17 19:58:18,961 - app - INFO - Input features: ['Economy (GDP per Capita)', 'Family', 'Health (Life Expectancy)', 'Freedom', 'Trust (Government Corruption)', 'Generosity']
2024-11-17 19:58:18,971 - app - INFO - Prediction log: {'timestamp': '2024-11-17T19:58:18.971596', 'input_data': {'Economy (GDP per Capita)': 0.01, 'Family': 0.01, 'Health (Life Expectancy)': 0.01, 'Freedom': 0, 'Trust (Government Corruption)': 0.01, 'Generosity': 0.01}, 'prediction': 3.4381875138888893, 'success': True, 'error': None, 'client_ip': '127.0.0.1'}
2024-11-17 20:00:09,402 - app - INFO - Input data shape: (1, 6)
2024-11-17 20:00:09,403 - app - INFO - Input features: ['Economy (GDP per Capita)', 'Family', 'Health (Life Expectancy)', 'Freedom', 'Trust (Government Corruption)', 'Generosity']
2024-11-17 20:00:09,412 - app - INFO - Prediction log: {'timestamp': '2024-11-17T20:00:09.412508', 'input_data': {'Economy (GDP per Capita)': 0.01, 'Family': 0.01, 'Health (Life Expectancy)': 0.01, 'Freedom': 0, 'Trust (Government Corruption)': 0.11, 'Generosity': 0.01}, 'prediction': 3.2609920317460315, 'success': True, 'error': None, 'client_ip': '127.0.0.1'}
2024-11-17 20:00:22,775 - app - INFO - Input data shape: (1, 6)
2024-11-17 20:00:22,775 - app - INFO - Input features: ['Economy (GDP per Capita)', 'Family', 'Health (Life Expectancy)', 'Freedom', 'Trust (Government Corruption)', 'Generosity']
2024-11-17 20:00:22,784 - app - INFO - Prediction log: {'timestamp': '2024-11-17T20:00:22.784431', 'input_data': {'Economy (GDP per Capita)': 0.01, 'Family': 0.01, 'Health (Life Expectancy)': 0.01, 'Freedom': 0, 'Trust (Government Corruption)': 0.11, 'Generosity': 0.26}, 'prediction': 3.359466734126982, 'success': True, 'error': None, 'client_ip': '127.0.0.1'}
2024-11-17 20:00:33,941 - app - INFO - Input data shape: (1, 6)
2024-11-17 20:00:33,941 - app - INFO - Input features: ['Economy (GDP per Capita)', 'Family', 'Health (Life Expectancy)', 'Freedom', 'Trust (Government Corruption)', 'Generosity']
2024-11-17 20:00:33,950 - app - INFO - Prediction log: {'timestamp': '2024-11-17T20:00:33.950473', 'input_data': {'Economy (GDP per Capita)': 0.01, 'Family': 0.01, 'Health (Life Expectancy)': 0.01, 'Freedom': 0, 'Trust (Government Corruption)': 0.11, 'Generosity': 1}, 'prediction': 3.378418817460315, 'success': True, 'error': None, 'client_ip': '127.0.0.1'}
2024-11-17 20:00:44,028 - app - INFO - Input data shape: (1, 6)
2024-11-17 20:00:44,028 - app - INFO - Input features: ['Economy (GDP per Capita)', 'Family', 'Health (Life Expectancy)', 'Freedom', 'Trust (Government Corruption)', 'Generosity']
2024-11-17 20:00:44,037 - app - INFO - Prediction log: {'timestamp': '2024-11-17T20:00:44.037342', 'input_data': {'Economy (GDP per Capita)': 0.01, 'Family': 0.01, 'Health (Life Expectancy)': 0.01, 'Freedom': 0, 'Trust (Government Corruption)': 0.11, 'Generosity': 2}, 'prediction': 3.378418817460315, 'success': True, 'error': None, 'client_ip': '127.0.0.1'}
2024-11-17 20:00:53,477 - app - INFO - Input data shape: (1, 6)
2024-11-17 20:00:53,478 - app - INFO - Input features: ['Economy (GDP per Capita)', 'Family', 'Health (Life Expectancy)', 'Freedom', 'Trust (Government Corruption)', 'Generosity']
2024-11-17 20:00:53,487 - app - INFO - Prediction log: {'timestamp': '2024-11-17T20:00:53.487123', 'input_data': {'Economy (GDP per Capita)': 0.01, 'Family': 0.01, 'Health (Life Expectancy)': 1, 'Freedom': 0, 'Trust (Government Corruption)': 0.11, 'Generosity': 2}, 'prediction': 4.043304908730153, 'success': True, 'error': None, 'client_ip': '127.0.0.1'}
2024-11-17 20:14:35,282 - app - INFO - Input data shape: (1, 6)
2024-11-17 20:14:35,283 - app - INFO - Input features: ['Economy (GDP per Capita)', 'Family', 'Health (Life Expectancy)', 'Freedom', 'Trust (Government Corruption)', 'Generosity']
2024-11-17 20:14:35,291 - app - INFO - Prediction log: {'timestamp': '2024-11-17T20:14:35.291763', 'input_data': {'Economy (GDP per Capita)': 0.03, 'Family': 0.03, 'Health (Life Expectancy)': 0.04, 'Freedom': 0.05, 'Trust (Government Corruption)': 0.04, 'Generosity': 0.04}, 'prediction': 3.4768400138888906, 'success': True, 'error': None, 'client_ip': '127.0.0.1'}
2024-11-17 20:47:32,083 - app - INFO - Input data shape: (1, 6)
2024-11-17 20:47:32,083 - app - INFO - Input features: ['Economy (GDP per Capita)', 'Family', 'Health (Life Expectancy)', 'Freedom', 'Trust (Government Corruption)', 'Generosity']
2024-11-17 20:47:32,092 - app - INFO - Prediction log: {'timestamp': '2024-11-17T20:47:32.092595', 'input_data': {'Economy (GDP per Capita)': 0.03, 'Family': 0.03, 'Health (Life Expectancy)': 0.04, 'Freedom': 0.05, 'Trust (Government Corruption)': 0.04, 'Generosity': 0.04}, 'prediction': 3.4768400138888906, 'success': True, 'error': None, 'client_ip': '127.0.0.1'}
2024-11-17 20:51:12,575 - app - ERROR - Exception on /favicon.ico [GET]
Traceback (most recent call last):
  File "/usr/local/python/3.12.1/lib/python3.12/site-packages/flask/app.py", line 1823, in full_dispatch_request
    rv = self.dispatch_request()
         ^^^^^^^^^^^^^^^^^^^^^^^
  File "/usr/local/python/3.12.1/lib/python3.12/site-packages/flask/app.py", line 1788, in dispatch_request
    self.raise_routing_exception(req)
  File "/usr/local/python/3.12.1/lib/python3.12/site-packages/flask/app.py", line 1770, in raise_routing_exception
    raise request.routing_exception  # type: ignore
    ^^^^^^^^^^^^^^^^^^^^^^^^^^^^^^^
  File "/usr/local/python/3.12.1/lib/python3.12/site-packages/flask/ctx.py", line 351, in match_request
    result = self.url_adapter.match(return_rule=True)  # type: ignore
             ^^^^^^^^^^^^^^^^^^^^^^^^^^^^^^^^^^^^^^^^
  File "/usr/local/python/3.12.1/lib/python3.12/site-packages/werkzeug/routing/map.py", line 624, in match
    raise NotFound() from None
werkzeug.exceptions.NotFound: 404 Not Found: The requested URL was not found on the server. If you entered the URL manually please check your spelling and try again.

During handling of the above exception, another exception occurred:

Traceback (most recent call last):
  File "/usr/local/python/3.12.1/lib/python3.12/site-packages/flask/app.py", line 2529, in wsgi_app
    response = self.full_dispatch_request()
               ^^^^^^^^^^^^^^^^^^^^^^^^^^^^
  File "/usr/local/python/3.12.1/lib/python3.12/site-packages/flask/app.py", line 1825, in full_dispatch_request
    rv = self.handle_user_exception(e)
         ^^^^^^^^^^^^^^^^^^^^^^^^^^^^^
  File "/usr/local/python/3.12.1/lib/python3.12/site-packages/flask_cors/extension.py", line 194, in wrapped_function
    return cors_after_request(app.make_response(f(*args, **kwargs)))
                                                ^^^^^^^^^^^^^^^^^^
  File "/usr/local/python/3.12.1/lib/python3.12/site-packages/flask/app.py", line 1669, in handle_user_exception
    return self.handle_http_exception(e)
           ^^^^^^^^^^^^^^^^^^^^^^^^^^^^^
  File "/usr/local/python/3.12.1/lib/python3.12/site-packages/flask/app.py", line 1609, in handle_http_exception
    return self.ensure_sync(handler)(e)
           ^^^^^^^^^^^^^^^^^^^^^^^^^^^^
  File "/workspaces/happiness_prediction/app/app.py", line 207, in not_found_error
    return render_template('error.html',
          ^^^^^^^^^^^^^^^^^^^^^^^^^^^^^
  File "/usr/local/python/3.12.1/lib/python3.12/site-packages/flask/templating.py", line 146, in render_template
    template = app.jinja_env.get_or_select_template(template_name_or_list)
               ^^^^^^^^^^^^^^^^^^^^^^^^^^^^^^^^^^^^^^^^^^^^^^^^^^^^^^^^^^^
  File "/home/codespace/.local/lib/python3.12/site-packages/jinja2/environment.py", line 1084, in get_or_select_template
    return self.get_template(template_name_or_list, parent, globals)
           ^^^^^^^^^^^^^^^^^^^^^^^^^^^^^^^^^^^^^^^^^^^^^^^^^^^^^^^^^
  File "/home/codespace/.local/lib/python3.12/site-packages/jinja2/environment.py", line 1013, in get_template
    return self._load_template(name, globals)
           ^^^^^^^^^^^^^^^^^^^^^^^^^^^^^^^^^^
  File "/home/codespace/.local/lib/python3.12/site-packages/jinja2/environment.py", line 972, in _load_template
    template = self.loader.load(self, name, self.make_globals(globals))
               ^^^^^^^^^^^^^^^^^^^^^^^^^^^^^^^^^^^^^^^^^^^^^^^^^^^^^^^^
  File "/home/codespace/.local/lib/python3.12/site-packages/jinja2/loaders.py", line 126, in load
    source, filename, uptodate = self.get_source(environment, name)
                                 ^^^^^^^^^^^^^^^^^^^^^^^^^^^^^^^^^^
  File "/usr/local/python/3.12.1/lib/python3.12/site-packages/flask/templating.py", line 62, in get_source
    return self._get_source_fast(environment, template)
           ^^^^^^^^^^^^^^^^^^^^^^^^^^^^^^^^^^^^^^^^^^^^
  File "/usr/local/python/3.12.1/lib/python3.12/site-packages/flask/templating.py", line 98, in _get_source_fast
    raise TemplateNotFound(template)
jinja2.exceptions.TemplateNotFound: error.html
2024-11-17 20:51:12,578 - app - ERROR - Server error: 500 Internal Server Error: The server encountered an internal error and was unable to complete your request. Either the server is overloaded or there is an error in the application.
Traceback (most recent call last):
  File "/usr/local/python/3.12.1/lib/python3.12/site-packages/flask/app.py", line 1823, in full_dispatch_request
    rv = self.dispatch_request()
         ^^^^^^^^^^^^^^^^^^^^^^^
  File "/usr/local/python/3.12.1/lib/python3.12/site-packages/flask/app.py", line 1788, in dispatch_request
    self.raise_routing_exception(req)
  File "/usr/local/python/3.12.1/lib/python3.12/site-packages/flask/app.py", line 1770, in raise_routing_exception
    raise request.routing_exception  # type: ignore
    ^^^^^^^^^^^^^^^^^^^^^^^^^^^^^^^
  File "/usr/local/python/3.12.1/lib/python3.12/site-packages/flask/ctx.py", line 351, in match_request
    result = self.url_adapter.match(return_rule=True)  # type: ignore
             ^^^^^^^^^^^^^^^^^^^^^^^^^^^^^^^^^^^^^^^^
  File "/usr/local/python/3.12.1/lib/python3.12/site-packages/werkzeug/routing/map.py", line 624, in match
    raise NotFound() from None
werkzeug.exceptions.NotFound: 404 Not Found: The requested URL was not found on the server. If you entered the URL manually please check your spelling and try again.

During handling of the above exception, another exception occurred:

Traceback (most recent call last):
  File "/usr/local/python/3.12.1/lib/python3.12/site-packages/flask/app.py", line 2529, in wsgi_app
    response = self.full_dispatch_request()
               ^^^^^^^^^^^^^^^^^^^^^^^^^^^^
  File "/usr/local/python/3.12.1/lib/python3.12/site-packages/flask/app.py", line 1825, in full_dispatch_request
    rv = self.handle_user_exception(e)
         ^^^^^^^^^^^^^^^^^^^^^^^^^^^^^
  File "/usr/local/python/3.12.1/lib/python3.12/site-packages/flask_cors/extension.py", line 194, in wrapped_function
    return cors_after_request(app.make_response(f(*args, **kwargs)))
                                                ^^^^^^^^^^^^^^^^^^
  File "/usr/local/python/3.12.1/lib/python3.12/site-packages/flask/app.py", line 1669, in handle_user_exception
    return self.handle_http_exception(e)
           ^^^^^^^^^^^^^^^^^^^^^^^^^^^^^
  File "/usr/local/python/3.12.1/lib/python3.12/site-packages/flask/app.py", line 1609, in handle_http_exception
    return self.ensure_sync(handler)(e)
           ^^^^^^^^^^^^^^^^^^^^^^^^^^^^
  File "/workspaces/happiness_prediction/app/app.py", line 207, in not_found_error
    return render_template('error.html',
          ^^^^^^^^^^^^^^^^^^^^^^^^^^^^^
  File "/usr/local/python/3.12.1/lib/python3.12/site-packages/flask/templating.py", line 146, in render_template
    template = app.jinja_env.get_or_select_template(template_name_or_list)
               ^^^^^^^^^^^^^^^^^^^^^^^^^^^^^^^^^^^^^^^^^^^^^^^^^^^^^^^^^^^
  File "/home/codespace/.local/lib/python3.12/site-packages/jinja2/environment.py", line 1084, in get_or_select_template
    return self.get_template(template_name_or_list, parent, globals)
           ^^^^^^^^^^^^^^^^^^^^^^^^^^^^^^^^^^^^^^^^^^^^^^^^^^^^^^^^^
  File "/home/codespace/.local/lib/python3.12/site-packages/jinja2/environment.py", line 1013, in get_template
    return self._load_template(name, globals)
           ^^^^^^^^^^^^^^^^^^^^^^^^^^^^^^^^^^
  File "/home/codespace/.local/lib/python3.12/site-packages/jinja2/environment.py", line 972, in _load_template
    template = self.loader.load(self, name, self.make_globals(globals))
               ^^^^^^^^^^^^^^^^^^^^^^^^^^^^^^^^^^^^^^^^^^^^^^^^^^^^^^^^
  File "/home/codespace/.local/lib/python3.12/site-packages/jinja2/loaders.py", line 126, in load
    source, filename, uptodate = self.get_source(environment, name)
                                 ^^^^^^^^^^^^^^^^^^^^^^^^^^^^^^^^^^
  File "/usr/local/python/3.12.1/lib/python3.12/site-packages/flask/templating.py", line 62, in get_source
    return self._get_source_fast(environment, template)
           ^^^^^^^^^^^^^^^^^^^^^^^^^^^^^^^^^^^^^^^^^^^^
  File "/usr/local/python/3.12.1/lib/python3.12/site-packages/flask/templating.py", line 98, in _get_source_fast
    raise TemplateNotFound(template)
jinja2.exceptions.TemplateNotFound: error.html

2024-11-17 20:51:41,149 - app - INFO - Input data shape: (1, 6)
2024-11-17 20:51:41,149 - app - INFO - Input features: ['Economy (GDP per Capita)', 'Family', 'Health (Life Expectancy)', 'Freedom', 'Trust (Government Corruption)', 'Generosity']
2024-11-17 20:51:41,158 - app - INFO - Prediction log: {'timestamp': '2024-11-17T20:51:41.158609', 'input_data': {'Economy (GDP per Capita)': 0.01, 'Family': 0.01, 'Health (Life Expectancy)': 0.02, 'Freedom': 0.01, 'Trust (Government Corruption)': 0.01, 'Generosity': 0.01}, 'prediction': 3.4381875138888893, 'success': True, 'error': None, 'client_ip': '127.0.0.1'}
2024-11-17 20:57:36,931 - app - INFO - Loading model artifacts...
2024-11-17 20:57:37,081 - app - INFO - Model artifacts loaded successfully
2024-11-17 20:57:37,081 - app - INFO - Model type: <class 'sklearn.ensemble._forest.RandomForestRegressor'>
2024-11-17 20:57:37,081 - app - INFO - Pipeline type: <class 'preprocessing_pipeline.PreprocessingPipeline'>
2024-11-17 20:57:37,081 - app - INFO - Loaded feature names: ['Economy (GDP per Capita)', 'Family', 'Health (Life Expectancy)', 'Freedom', 'Trust (Government Corruption)', 'Generosity']
2024-11-17 20:57:37,084 - app - INFO - Starting application on port 5000
2024-11-17 20:57:50,024 - app - ERROR - Exception on /favicon.ico [GET]
Traceback (most recent call last):
  File "/usr/local/python/3.12.1/lib/python3.12/site-packages/flask/app.py", line 1823, in full_dispatch_request
    rv = self.dispatch_request()
         ^^^^^^^^^^^^^^^^^^^^^^^
  File "/usr/local/python/3.12.1/lib/python3.12/site-packages/flask/app.py", line 1788, in dispatch_request
    self.raise_routing_exception(req)
  File "/usr/local/python/3.12.1/lib/python3.12/site-packages/flask/app.py", line 1770, in raise_routing_exception
    raise request.routing_exception  # type: ignore
    ^^^^^^^^^^^^^^^^^^^^^^^^^^^^^^^
  File "/usr/local/python/3.12.1/lib/python3.12/site-packages/flask/ctx.py", line 351, in match_request
    result = self.url_adapter.match(return_rule=True)  # type: ignore
             ^^^^^^^^^^^^^^^^^^^^^^^^^^^^^^^^^^^^^^^^
  File "/usr/local/python/3.12.1/lib/python3.12/site-packages/werkzeug/routing/map.py", line 624, in match
    raise NotFound() from None
werkzeug.exceptions.NotFound: 404 Not Found: The requested URL was not found on the server. If you entered the URL manually please check your spelling and try again.

During handling of the above exception, another exception occurred:

Traceback (most recent call last):
  File "/usr/local/python/3.12.1/lib/python3.12/site-packages/flask/app.py", line 2529, in wsgi_app
    response = self.full_dispatch_request()
               ^^^^^^^^^^^^^^^^^^^^^^^^^^^^
  File "/usr/local/python/3.12.1/lib/python3.12/site-packages/flask/app.py", line 1825, in full_dispatch_request
    rv = self.handle_user_exception(e)
         ^^^^^^^^^^^^^^^^^^^^^^^^^^^^^
  File "/usr/local/python/3.12.1/lib/python3.12/site-packages/flask_cors/extension.py", line 194, in wrapped_function
    return cors_after_request(app.make_response(f(*args, **kwargs)))
                                                ^^^^^^^^^^^^^^^^^^
  File "/usr/local/python/3.12.1/lib/python3.12/site-packages/flask/app.py", line 1669, in handle_user_exception
    return self.handle_http_exception(e)
           ^^^^^^^^^^^^^^^^^^^^^^^^^^^^^
  File "/usr/local/python/3.12.1/lib/python3.12/site-packages/flask/app.py", line 1609, in handle_http_exception
    return self.ensure_sync(handler)(e)
           ^^^^^^^^^^^^^^^^^^^^^^^^^^^^
  File "/workspaces/happiness_prediction/app/app.py", line 207, in not_found_error
    return render_template('error.html',
          ^^^^^^^^^^^^^^^^^^^^^^^^^^^^^
  File "/usr/local/python/3.12.1/lib/python3.12/site-packages/flask/templating.py", line 146, in render_template
    template = app.jinja_env.get_or_select_template(template_name_or_list)
               ^^^^^^^^^^^^^^^^^^^^^^^^^^^^^^^^^^^^^^^^^^^^^^^^^^^^^^^^^^^
  File "/home/codespace/.local/lib/python3.12/site-packages/jinja2/environment.py", line 1084, in get_or_select_template
    return self.get_template(template_name_or_list, parent, globals)
           ^^^^^^^^^^^^^^^^^^^^^^^^^^^^^^^^^^^^^^^^^^^^^^^^^^^^^^^^^
  File "/home/codespace/.local/lib/python3.12/site-packages/jinja2/environment.py", line 1013, in get_template
    return self._load_template(name, globals)
           ^^^^^^^^^^^^^^^^^^^^^^^^^^^^^^^^^^
  File "/home/codespace/.local/lib/python3.12/site-packages/jinja2/environment.py", line 972, in _load_template
    template = self.loader.load(self, name, self.make_globals(globals))
               ^^^^^^^^^^^^^^^^^^^^^^^^^^^^^^^^^^^^^^^^^^^^^^^^^^^^^^^^
  File "/home/codespace/.local/lib/python3.12/site-packages/jinja2/loaders.py", line 126, in load
    source, filename, uptodate = self.get_source(environment, name)
                                 ^^^^^^^^^^^^^^^^^^^^^^^^^^^^^^^^^^
  File "/usr/local/python/3.12.1/lib/python3.12/site-packages/flask/templating.py", line 62, in get_source
    return self._get_source_fast(environment, template)
           ^^^^^^^^^^^^^^^^^^^^^^^^^^^^^^^^^^^^^^^^^^^^
  File "/usr/local/python/3.12.1/lib/python3.12/site-packages/flask/templating.py", line 98, in _get_source_fast
    raise TemplateNotFound(template)
jinja2.exceptions.TemplateNotFound: error.html
2024-11-17 20:57:50,027 - app - ERROR - Server error: 500 Internal Server Error: The server encountered an internal error and was unable to complete your request. Either the server is overloaded or there is an error in the application.
Traceback (most recent call last):
  File "/usr/local/python/3.12.1/lib/python3.12/site-packages/flask/app.py", line 1823, in full_dispatch_request
    rv = self.dispatch_request()
         ^^^^^^^^^^^^^^^^^^^^^^^
  File "/usr/local/python/3.12.1/lib/python3.12/site-packages/flask/app.py", line 1788, in dispatch_request
    self.raise_routing_exception(req)
  File "/usr/local/python/3.12.1/lib/python3.12/site-packages/flask/app.py", line 1770, in raise_routing_exception
    raise request.routing_exception  # type: ignore
    ^^^^^^^^^^^^^^^^^^^^^^^^^^^^^^^
  File "/usr/local/python/3.12.1/lib/python3.12/site-packages/flask/ctx.py", line 351, in match_request
    result = self.url_adapter.match(return_rule=True)  # type: ignore
             ^^^^^^^^^^^^^^^^^^^^^^^^^^^^^^^^^^^^^^^^
  File "/usr/local/python/3.12.1/lib/python3.12/site-packages/werkzeug/routing/map.py", line 624, in match
    raise NotFound() from None
werkzeug.exceptions.NotFound: 404 Not Found: The requested URL was not found on the server. If you entered the URL manually please check your spelling and try again.

During handling of the above exception, another exception occurred:

Traceback (most recent call last):
  File "/usr/local/python/3.12.1/lib/python3.12/site-packages/flask/app.py", line 2529, in wsgi_app
    response = self.full_dispatch_request()
               ^^^^^^^^^^^^^^^^^^^^^^^^^^^^
  File "/usr/local/python/3.12.1/lib/python3.12/site-packages/flask/app.py", line 1825, in full_dispatch_request
    rv = self.handle_user_exception(e)
         ^^^^^^^^^^^^^^^^^^^^^^^^^^^^^
  File "/usr/local/python/3.12.1/lib/python3.12/site-packages/flask_cors/extension.py", line 194, in wrapped_function
    return cors_after_request(app.make_response(f(*args, **kwargs)))
                                                ^^^^^^^^^^^^^^^^^^
  File "/usr/local/python/3.12.1/lib/python3.12/site-packages/flask/app.py", line 1669, in handle_user_exception
    return self.handle_http_exception(e)
           ^^^^^^^^^^^^^^^^^^^^^^^^^^^^^
  File "/usr/local/python/3.12.1/lib/python3.12/site-packages/flask/app.py", line 1609, in handle_http_exception
    return self.ensure_sync(handler)(e)
           ^^^^^^^^^^^^^^^^^^^^^^^^^^^^
  File "/workspaces/happiness_prediction/app/app.py", line 207, in not_found_error
    return render_template('error.html',
          ^^^^^^^^^^^^^^^^^^^^^^^^^^^^^
  File "/usr/local/python/3.12.1/lib/python3.12/site-packages/flask/templating.py", line 146, in render_template
    template = app.jinja_env.get_or_select_template(template_name_or_list)
               ^^^^^^^^^^^^^^^^^^^^^^^^^^^^^^^^^^^^^^^^^^^^^^^^^^^^^^^^^^^
  File "/home/codespace/.local/lib/python3.12/site-packages/jinja2/environment.py", line 1084, in get_or_select_template
    return self.get_template(template_name_or_list, parent, globals)
           ^^^^^^^^^^^^^^^^^^^^^^^^^^^^^^^^^^^^^^^^^^^^^^^^^^^^^^^^^
  File "/home/codespace/.local/lib/python3.12/site-packages/jinja2/environment.py", line 1013, in get_template
    return self._load_template(name, globals)
           ^^^^^^^^^^^^^^^^^^^^^^^^^^^^^^^^^^
  File "/home/codespace/.local/lib/python3.12/site-packages/jinja2/environment.py", line 972, in _load_template
    template = self.loader.load(self, name, self.make_globals(globals))
               ^^^^^^^^^^^^^^^^^^^^^^^^^^^^^^^^^^^^^^^^^^^^^^^^^^^^^^^^
  File "/home/codespace/.local/lib/python3.12/site-packages/jinja2/loaders.py", line 126, in load
    source, filename, uptodate = self.get_source(environment, name)
                                 ^^^^^^^^^^^^^^^^^^^^^^^^^^^^^^^^^^
  File "/usr/local/python/3.12.1/lib/python3.12/site-packages/flask/templating.py", line 62, in get_source
    return self._get_source_fast(environment, template)
           ^^^^^^^^^^^^^^^^^^^^^^^^^^^^^^^^^^^^^^^^^^^^
  File "/usr/local/python/3.12.1/lib/python3.12/site-packages/flask/templating.py", line 98, in _get_source_fast
    raise TemplateNotFound(template)
jinja2.exceptions.TemplateNotFound: error.html

2024-11-17 20:58:04,430 - app - INFO - Input data shape: (1, 6)
2024-11-17 20:58:04,430 - app - INFO - Input features: ['Economy (GDP per Capita)', 'Family', 'Health (Life Expectancy)', 'Freedom', 'Trust (Government Corruption)', 'Generosity']
2024-11-17 20:58:04,442 - app - INFO - Prediction log: {'timestamp': '2024-11-17T20:58:04.442429', 'input_data': {'Economy (GDP per Capita)': 0.01, 'Family': 0.01, 'Health (Life Expectancy)': 0.01, 'Freedom': 0.01, 'Trust (Government Corruption)': 0.01, 'Generosity': 0.01}, 'prediction': 3.4381875138888893, 'success': True, 'error': None, 'client_ip': '127.0.0.1'}
2024-11-18 05:55:37,532 - app.app - INFO - Loading model artifacts...
2024-11-18 05:55:37,628 - app.app - INFO - Loading model artifacts...
2024-11-18 05:55:37,711 - app.app - ERROR - Error loading model artifacts: No module named 'numpy._core'
Traceback (most recent call last):
  File "/app/app/app.py", line 63, in load_model_artifacts
    model_data = joblib.load(app.config['MODEL_PATH'])
  File "/usr/local/lib/python3.9/site-packages/joblib/numpy_pickle.py", line 585, in load
    obj = _unpickle(fobj, filename, mmap_mode)
  File "/usr/local/lib/python3.9/site-packages/joblib/numpy_pickle.py", line 504, in _unpickle
    obj = unpickler.load()
  File "/usr/local/lib/python3.9/pickle.py", line 1212, in load
    dispatch[key[0]](self)
  File "/usr/local/lib/python3.9/site-packages/joblib/numpy_pickle.py", line 342, in load_build
    self.stack.append(array_wrapper.read(self))
  File "/usr/local/lib/python3.9/site-packages/joblib/numpy_pickle.py", line 187, in read
    array = self.read_array(unpickler)
  File "/usr/local/lib/python3.9/site-packages/joblib/numpy_pickle.py", line 121, in read_array
    array = pickle.load(unpickler.file_handle)
ModuleNotFoundError: No module named 'numpy._core'

2024-11-18 05:55:37,713 - app.app - ERROR - Failed to load model artifacts: No module named 'numpy._core'
2024-11-18 05:55:37,728 - app.app - INFO - Loading model artifacts...
2024-11-18 05:55:37,758 - app.app - ERROR - Error loading model artifacts: No module named 'numpy._core'
Traceback (most recent call last):
  File "/app/app/app.py", line 63, in load_model_artifacts
    model_data = joblib.load(app.config['MODEL_PATH'])
  File "/usr/local/lib/python3.9/site-packages/joblib/numpy_pickle.py", line 585, in load
    obj = _unpickle(fobj, filename, mmap_mode)
  File "/usr/local/lib/python3.9/site-packages/joblib/numpy_pickle.py", line 504, in _unpickle
    obj = unpickler.load()
  File "/usr/local/lib/python3.9/pickle.py", line 1212, in load
    dispatch[key[0]](self)
  File "/usr/local/lib/python3.9/site-packages/joblib/numpy_pickle.py", line 342, in load_build
    self.stack.append(array_wrapper.read(self))
  File "/usr/local/lib/python3.9/site-packages/joblib/numpy_pickle.py", line 187, in read
    array = self.read_array(unpickler)
  File "/usr/local/lib/python3.9/site-packages/joblib/numpy_pickle.py", line 121, in read_array
    array = pickle.load(unpickler.file_handle)
ModuleNotFoundError: No module named 'numpy._core'

2024-11-18 05:55:37,759 - app.app - ERROR - Failed to load model artifacts: No module named 'numpy._core'
2024-11-18 05:55:37,770 - app.app - INFO - Loading model artifacts...
2024-11-18 05:55:37,876 - app.app - ERROR - Error loading model artifacts: No module named 'numpy._core'
Traceback (most recent call last):
  File "/app/app/app.py", line 63, in load_model_artifacts
    model_data = joblib.load(app.config['MODEL_PATH'])
  File "/usr/local/lib/python3.9/site-packages/joblib/numpy_pickle.py", line 585, in load
    obj = _unpickle(fobj, filename, mmap_mode)
  File "/usr/local/lib/python3.9/site-packages/joblib/numpy_pickle.py", line 504, in _unpickle
    obj = unpickler.load()
  File "/usr/local/lib/python3.9/pickle.py", line 1212, in load
    dispatch[key[0]](self)
  File "/usr/local/lib/python3.9/site-packages/joblib/numpy_pickle.py", line 342, in load_build
    self.stack.append(array_wrapper.read(self))
  File "/usr/local/lib/python3.9/site-packages/joblib/numpy_pickle.py", line 187, in read
    array = self.read_array(unpickler)
  File "/usr/local/lib/python3.9/site-packages/joblib/numpy_pickle.py", line 121, in read_array
    array = pickle.load(unpickler.file_handle)
ModuleNotFoundError: No module named 'numpy._core'

2024-11-18 05:55:37,877 - app.app - ERROR - Failed to load model artifacts: No module named 'numpy._core'
2024-11-18 05:55:37,888 - app.app - ERROR - Error loading model artifacts: No module named 'numpy._core'
Traceback (most recent call last):
  File "/app/app/app.py", line 63, in load_model_artifacts
    model_data = joblib.load(app.config['MODEL_PATH'])
  File "/usr/local/lib/python3.9/site-packages/joblib/numpy_pickle.py", line 585, in load
    obj = _unpickle(fobj, filename, mmap_mode)
  File "/usr/local/lib/python3.9/site-packages/joblib/numpy_pickle.py", line 504, in _unpickle
    obj = unpickler.load()
  File "/usr/local/lib/python3.9/pickle.py", line 1212, in load
    dispatch[key[0]](self)
  File "/usr/local/lib/python3.9/site-packages/joblib/numpy_pickle.py", line 342, in load_build
    self.stack.append(array_wrapper.read(self))
  File "/usr/local/lib/python3.9/site-packages/joblib/numpy_pickle.py", line 187, in read
    array = self.read_array(unpickler)
  File "/usr/local/lib/python3.9/site-packages/joblib/numpy_pickle.py", line 121, in read_array
    array = pickle.load(unpickler.file_handle)
ModuleNotFoundError: No module named 'numpy._core'

2024-11-18 05:55:37,888 - app.app - ERROR - Failed to load model artifacts: No module named 'numpy._core'
2024-11-18 06:04:09,733 - app.app - INFO - Loading model artifacts...
2024-11-18 06:04:09,743 - app.app - INFO - Loading model artifacts...
2024-11-18 06:04:09,789 - app.app - INFO - Loading model artifacts...
2024-11-18 06:04:09,804 - app.app - INFO - Loading model artifacts...
2024-11-18 06:04:10,196 - app.app - ERROR - Error loading model artifacts: Can't get attribute 'PreprocessingPipeline' on <module 'gunicorn.__main__' from '/usr/local/lib/python3.9/site-packages/gunicorn/__main__.py'>
Traceback (most recent call last):
  File "/app/app/app.py", line 66, in load_model_artifacts
    pipeline = PreprocessingPipeline.load(app.config['PIPELINE_PATH'])
  File "/app/src/preprocessing_pipeline.py", line 163, in load
    return joblib.load(path)
  File "/usr/local/lib/python3.9/site-packages/joblib/numpy_pickle.py", line 658, in load
    obj = _unpickle(fobj, filename, mmap_mode)
  File "/usr/local/lib/python3.9/site-packages/joblib/numpy_pickle.py", line 577, in _unpickle
    obj = unpickler.load()
  File "/usr/local/lib/python3.9/pickle.py", line 1212, in load
    dispatch[key[0]](self)
  File "/usr/local/lib/python3.9/pickle.py", line 1537, in load_stack_global
    self.append(self.find_class(module, name))
  File "/usr/local/lib/python3.9/pickle.py", line 1581, in find_class
    return _getattribute(sys.modules[module], name)[0]
  File "/usr/local/lib/python3.9/pickle.py", line 331, in _getattribute
    raise AttributeError("Can't get attribute {!r} on {!r}"
AttributeError: Can't get attribute 'PreprocessingPipeline' on <module 'gunicorn.__main__' from '/usr/local/lib/python3.9/site-packages/gunicorn/__main__.py'>

2024-11-18 06:04:10,197 - app.app - ERROR - Failed to load model artifacts: Can't get attribute 'PreprocessingPipeline' on <module 'gunicorn.__main__' from '/usr/local/lib/python3.9/site-packages/gunicorn/__main__.py'>
2024-11-18 06:04:10,201 - app.app - ERROR - Error loading model artifacts: Can't get attribute 'PreprocessingPipeline' on <module 'gunicorn.__main__' from '/usr/local/lib/python3.9/site-packages/gunicorn/__main__.py'>
Traceback (most recent call last):
  File "/app/app/app.py", line 66, in load_model_artifacts
    pipeline = PreprocessingPipeline.load(app.config['PIPELINE_PATH'])
  File "/app/src/preprocessing_pipeline.py", line 163, in load
    return joblib.load(path)
  File "/usr/local/lib/python3.9/site-packages/joblib/numpy_pickle.py", line 658, in load
    obj = _unpickle(fobj, filename, mmap_mode)
  File "/usr/local/lib/python3.9/site-packages/joblib/numpy_pickle.py", line 577, in _unpickle
    obj = unpickler.load()
  File "/usr/local/lib/python3.9/pickle.py", line 1212, in load
    dispatch[key[0]](self)
  File "/usr/local/lib/python3.9/pickle.py", line 1537, in load_stack_global
    self.append(self.find_class(module, name))
  File "/usr/local/lib/python3.9/pickle.py", line 1581, in find_class
    return _getattribute(sys.modules[module], name)[0]
  File "/usr/local/lib/python3.9/pickle.py", line 331, in _getattribute
    raise AttributeError("Can't get attribute {!r} on {!r}"
AttributeError: Can't get attribute 'PreprocessingPipeline' on <module 'gunicorn.__main__' from '/usr/local/lib/python3.9/site-packages/gunicorn/__main__.py'>

2024-11-18 06:04:10,202 - app.app - ERROR - Failed to load model artifacts: Can't get attribute 'PreprocessingPipeline' on <module 'gunicorn.__main__' from '/usr/local/lib/python3.9/site-packages/gunicorn/__main__.py'>
2024-11-18 06:04:10,210 - app.app - ERROR - Error loading model artifacts: Can't get attribute 'PreprocessingPipeline' on <module 'gunicorn.__main__' from '/usr/local/lib/python3.9/site-packages/gunicorn/__main__.py'>
Traceback (most recent call last):
  File "/app/app/app.py", line 66, in load_model_artifacts
    pipeline = PreprocessingPipeline.load(app.config['PIPELINE_PATH'])
  File "/app/src/preprocessing_pipeline.py", line 163, in load
    return joblib.load(path)
  File "/usr/local/lib/python3.9/site-packages/joblib/numpy_pickle.py", line 658, in load
    obj = _unpickle(fobj, filename, mmap_mode)
  File "/usr/local/lib/python3.9/site-packages/joblib/numpy_pickle.py", line 577, in _unpickle
    obj = unpickler.load()
  File "/usr/local/lib/python3.9/pickle.py", line 1212, in load
    dispatch[key[0]](self)
  File "/usr/local/lib/python3.9/pickle.py", line 1537, in load_stack_global
    self.append(self.find_class(module, name))
  File "/usr/local/lib/python3.9/pickle.py", line 1581, in find_class
    return _getattribute(sys.modules[module], name)[0]
  File "/usr/local/lib/python3.9/pickle.py", line 331, in _getattribute
    raise AttributeError("Can't get attribute {!r} on {!r}"
AttributeError: Can't get attribute 'PreprocessingPipeline' on <module 'gunicorn.__main__' from '/usr/local/lib/python3.9/site-packages/gunicorn/__main__.py'>

2024-11-18 06:04:10,210 - app.app - ERROR - Failed to load model artifacts: Can't get attribute 'PreprocessingPipeline' on <module 'gunicorn.__main__' from '/usr/local/lib/python3.9/site-packages/gunicorn/__main__.py'>
2024-11-18 06:04:10,218 - app.app - ERROR - Error loading model artifacts: Can't get attribute 'PreprocessingPipeline' on <module 'gunicorn.__main__' from '/usr/local/lib/python3.9/site-packages/gunicorn/__main__.py'>
Traceback (most recent call last):
  File "/app/app/app.py", line 66, in load_model_artifacts
    pipeline = PreprocessingPipeline.load(app.config['PIPELINE_PATH'])
  File "/app/src/preprocessing_pipeline.py", line 163, in load
    return joblib.load(path)
  File "/usr/local/lib/python3.9/site-packages/joblib/numpy_pickle.py", line 658, in load
    obj = _unpickle(fobj, filename, mmap_mode)
  File "/usr/local/lib/python3.9/site-packages/joblib/numpy_pickle.py", line 577, in _unpickle
    obj = unpickler.load()
  File "/usr/local/lib/python3.9/pickle.py", line 1212, in load
    dispatch[key[0]](self)
  File "/usr/local/lib/python3.9/pickle.py", line 1537, in load_stack_global
    self.append(self.find_class(module, name))
  File "/usr/local/lib/python3.9/pickle.py", line 1581, in find_class
    return _getattribute(sys.modules[module], name)[0]
  File "/usr/local/lib/python3.9/pickle.py", line 331, in _getattribute
    raise AttributeError("Can't get attribute {!r} on {!r}"
AttributeError: Can't get attribute 'PreprocessingPipeline' on <module 'gunicorn.__main__' from '/usr/local/lib/python3.9/site-packages/gunicorn/__main__.py'>

2024-11-18 06:04:10,218 - app.app - ERROR - Failed to load model artifacts: Can't get attribute 'PreprocessingPipeline' on <module 'gunicorn.__main__' from '/usr/local/lib/python3.9/site-packages/gunicorn/__main__.py'>
2024-11-18 06:16:39,659 - app.app - INFO - Loading model artifacts...
2024-11-18 06:16:39,704 - app.app - INFO - Loading model artifacts...
2024-11-18 06:16:39,758 - app.app - INFO - Loading model artifacts...
2024-11-18 06:16:39,806 - app.app - INFO - Loading model artifacts...
2024-11-18 06:16:40,211 - app.app - ERROR - Error loading model artifacts: Can't get attribute 'PreprocessingPipeline' on <module '__main__' from '/usr/local/bin/gunicorn'>
Traceback (most recent call last):
  File "/app/app/app.py", line 66, in load_model_artifacts
    pipeline = PreprocessingPipeline.load(app.config['PIPELINE_PATH'])
  File "/app/src/preprocessing_pipeline.py", line 163, in load
    return joblib.load(path)
  File "/usr/local/lib/python3.9/site-packages/joblib/numpy_pickle.py", line 658, in load
    obj = _unpickle(fobj, filename, mmap_mode)
  File "/usr/local/lib/python3.9/site-packages/joblib/numpy_pickle.py", line 577, in _unpickle
    obj = unpickler.load()
  File "/usr/local/lib/python3.9/pickle.py", line 1212, in load
    dispatch[key[0]](self)
  File "/usr/local/lib/python3.9/pickle.py", line 1537, in load_stack_global
    self.append(self.find_class(module, name))
  File "/usr/local/lib/python3.9/pickle.py", line 1581, in find_class
    return _getattribute(sys.modules[module], name)[0]
  File "/usr/local/lib/python3.9/pickle.py", line 331, in _getattribute
    raise AttributeError("Can't get attribute {!r} on {!r}"
AttributeError: Can't get attribute 'PreprocessingPipeline' on <module '__main__' from '/usr/local/bin/gunicorn'>

2024-11-18 06:16:40,211 - app.app - ERROR - Failed to load model artifacts: Can't get attribute 'PreprocessingPipeline' on <module '__main__' from '/usr/local/bin/gunicorn'>
2024-11-18 06:16:40,211 - app.app - ERROR - Error loading model artifacts: Can't get attribute 'PreprocessingPipeline' on <module '__main__' from '/usr/local/bin/gunicorn'>
Traceback (most recent call last):
  File "/app/app/app.py", line 66, in load_model_artifacts
    pipeline = PreprocessingPipeline.load(app.config['PIPELINE_PATH'])
  File "/app/src/preprocessing_pipeline.py", line 163, in load
    return joblib.load(path)
  File "/usr/local/lib/python3.9/site-packages/joblib/numpy_pickle.py", line 658, in load
    obj = _unpickle(fobj, filename, mmap_mode)
  File "/usr/local/lib/python3.9/site-packages/joblib/numpy_pickle.py", line 577, in _unpickle
    obj = unpickler.load()
  File "/usr/local/lib/python3.9/pickle.py", line 1212, in load
    dispatch[key[0]](self)
  File "/usr/local/lib/python3.9/pickle.py", line 1537, in load_stack_global
    self.append(self.find_class(module, name))
  File "/usr/local/lib/python3.9/pickle.py", line 1581, in find_class
    return _getattribute(sys.modules[module], name)[0]
  File "/usr/local/lib/python3.9/pickle.py", line 331, in _getattribute
    raise AttributeError("Can't get attribute {!r} on {!r}"
AttributeError: Can't get attribute 'PreprocessingPipeline' on <module '__main__' from '/usr/local/bin/gunicorn'>

2024-11-18 06:16:40,210 - app.app - ERROR - Error loading model artifacts: Can't get attribute 'PreprocessingPipeline' on <module '__main__' from '/usr/local/bin/gunicorn'>
Traceback (most recent call last):
  File "/app/app/app.py", line 66, in load_model_artifacts
    pipeline = PreprocessingPipeline.load(app.config['PIPELINE_PATH'])
  File "/app/src/preprocessing_pipeline.py", line 163, in load
    return joblib.load(path)
  File "/usr/local/lib/python3.9/site-packages/joblib/numpy_pickle.py", line 658, in load
    obj = _unpickle(fobj, filename, mmap_mode)
  File "/usr/local/lib/python3.9/site-packages/joblib/numpy_pickle.py", line 577, in _unpickle
    obj = unpickler.load()
  File "/usr/local/lib/python3.9/pickle.py", line 1212, in load
    dispatch[key[0]](self)
  File "/usr/local/lib/python3.9/pickle.py", line 1537, in load_stack_global
    self.append(self.find_class(module, name))
  File "/usr/local/lib/python3.9/pickle.py", line 1581, in find_class
    return _getattribute(sys.modules[module], name)[0]
  File "/usr/local/lib/python3.9/pickle.py", line 331, in _getattribute
    raise AttributeError("Can't get attribute {!r} on {!r}"
AttributeError: Can't get attribute 'PreprocessingPipeline' on <module '__main__' from '/usr/local/bin/gunicorn'>

2024-11-18 06:16:40,212 - app.app - ERROR - Failed to load model artifacts: Can't get attribute 'PreprocessingPipeline' on <module '__main__' from '/usr/local/bin/gunicorn'>
2024-11-18 06:16:40,212 - app.app - ERROR - Failed to load model artifacts: Can't get attribute 'PreprocessingPipeline' on <module '__main__' from '/usr/local/bin/gunicorn'>
2024-11-18 06:16:40,243 - app.app - ERROR - Error loading model artifacts: Can't get attribute 'PreprocessingPipeline' on <module '__main__' from '/usr/local/bin/gunicorn'>
Traceback (most recent call last):
  File "/app/app/app.py", line 66, in load_model_artifacts
    pipeline = PreprocessingPipeline.load(app.config['PIPELINE_PATH'])
  File "/app/src/preprocessing_pipeline.py", line 163, in load
    return joblib.load(path)
  File "/usr/local/lib/python3.9/site-packages/joblib/numpy_pickle.py", line 658, in load
    obj = _unpickle(fobj, filename, mmap_mode)
  File "/usr/local/lib/python3.9/site-packages/joblib/numpy_pickle.py", line 577, in _unpickle
    obj = unpickler.load()
  File "/usr/local/lib/python3.9/pickle.py", line 1212, in load
    dispatch[key[0]](self)
  File "/usr/local/lib/python3.9/pickle.py", line 1537, in load_stack_global
    self.append(self.find_class(module, name))
  File "/usr/local/lib/python3.9/pickle.py", line 1581, in find_class
    return _getattribute(sys.modules[module], name)[0]
  File "/usr/local/lib/python3.9/pickle.py", line 331, in _getattribute
    raise AttributeError("Can't get attribute {!r} on {!r}"
AttributeError: Can't get attribute 'PreprocessingPipeline' on <module '__main__' from '/usr/local/bin/gunicorn'>

2024-11-18 06:16:40,243 - app.app - ERROR - Failed to load model artifacts: Can't get attribute 'PreprocessingPipeline' on <module '__main__' from '/usr/local/bin/gunicorn'>
2024-11-18 10:19:41,531 - app - INFO - Loading model artifacts...
2024-11-18 10:19:41,918 - app - INFO - Model artifacts loaded successfully
2024-11-18 10:19:41,918 - app - INFO - Model type: <class 'sklearn.ensemble._forest.RandomForestRegressor'>
2024-11-18 10:19:41,919 - app - INFO - Pipeline type: <class 'preprocessing_pipeline.PreprocessingPipeline'>
2024-11-18 10:19:41,919 - app - INFO - Loaded feature names: ['Economy (GDP per Capita)', 'Family', 'Health (Life Expectancy)', 'Freedom', 'Trust (Government Corruption)', 'Generosity']
2024-11-18 10:19:41,921 - app - INFO - Starting application on port 5000
2024-11-18 10:20:05,735 - app - INFO - Input data shape: (1, 6)
2024-11-18 10:20:05,735 - app - INFO - Input features: ['Economy (GDP per Capita)', 'Family', 'Health (Life Expectancy)', 'Freedom', 'Trust (Government Corruption)', 'Generosity']
2024-11-18 10:20:05,746 - app - INFO - Prediction log: {'timestamp': '2024-11-18T10:20:05.746884', 'input_data': {'Economy (GDP per Capita)': 0.01, 'Family': 0.01, 'Health (Life Expectancy)': 0.01, 'Freedom': 0.02, 'Trust (Government Corruption)': 0.01, 'Generosity': 0.01}, 'prediction': 3.4381875138888893, 'success': True, 'error': None, 'client_ip': '127.0.0.1'}
2024-11-18 10:21:04,611 - app - INFO - Input data shape: (1, 6)
2024-11-18 10:21:04,612 - app - INFO - Input features: ['Economy (GDP per Capita)', 'Family', 'Health (Life Expectancy)', 'Freedom', 'Trust (Government Corruption)', 'Generosity']
2024-11-18 10:21:04,621 - app - INFO - Prediction log: {'timestamp': '2024-11-18T10:21:04.621202', 'input_data': {'Economy (GDP per Capita)': 0.01, 'Family': 0.01, 'Health (Life Expectancy)': 1, 'Freedom': 0.02, 'Trust (Government Corruption)': 0.01, 'Generosity': 0.01}, 'prediction': 4.207730940476188, 'success': True, 'error': None, 'client_ip': '127.0.0.1'}
2024-11-18 10:21:12,223 - app - INFO - Input data shape: (1, 6)
2024-11-18 10:21:12,224 - app - INFO - Input features: ['Economy (GDP per Capita)', 'Family', 'Health (Life Expectancy)', 'Freedom', 'Trust (Government Corruption)', 'Generosity']
2024-11-18 10:21:12,241 - app - INFO - Prediction log: {'timestamp': '2024-11-18T10:21:12.241271', 'input_data': {'Economy (GDP per Capita)': 0.01, 'Family': 0.01, 'Health (Life Expectancy)': 2, 'Freedom': 0.02, 'Trust (Government Corruption)': 0.01, 'Generosity': 0.01}, 'prediction': 4.207730940476188, 'success': True, 'error': None, 'client_ip': '127.0.0.1'}
2024-11-18 10:21:22,731 - app - INFO - Input data shape: (1, 6)
2024-11-18 10:21:22,731 - app - INFO - Input features: ['Economy (GDP per Capita)', 'Family', 'Health (Life Expectancy)', 'Freedom', 'Trust (Government Corruption)', 'Generosity']
2024-11-18 10:21:22,740 - app - INFO - Prediction log: {'timestamp': '2024-11-18T10:21:22.740115', 'input_data': {'Economy (GDP per Capita)': 0.01, 'Family': 0.01, 'Health (Life Expectancy)': 2, 'Freedom': 1, 'Trust (Government Corruption)': 0.01, 'Generosity': 0.01}, 'prediction': 4.738892468253966, 'success': True, 'error': None, 'client_ip': '127.0.0.1'}
2024-11-18 10:21:31,522 - app - INFO - Input data shape: (1, 6)
2024-11-18 10:21:31,522 - app - INFO - Input features: ['Economy (GDP per Capita)', 'Family', 'Health (Life Expectancy)', 'Freedom', 'Trust (Government Corruption)', 'Generosity']
2024-11-18 10:21:31,531 - app - INFO - Prediction log: {'timestamp': '2024-11-18T10:21:31.531403', 'input_data': {'Economy (GDP per Capita)': 1, 'Family': 0.01, 'Health (Life Expectancy)': 2, 'Freedom': 1, 'Trust (Government Corruption)': 0.01, 'Generosity': 0.01}, 'prediction': 5.614382593253964, 'success': True, 'error': None, 'client_ip': '127.0.0.1'}
2024-11-18 12:54:06,723 - app - INFO - Loading model artifacts...
2024-11-18 12:54:07,254 - app - INFO - Model artifacts loaded successfully
2024-11-18 12:54:07,254 - app - INFO - Model type: <class 'sklearn.ensemble._forest.RandomForestRegressor'>
2024-11-18 12:54:07,255 - app - INFO - Pipeline type: <class 'preprocessing_pipeline.PreprocessingPipeline'>
2024-11-18 12:54:07,255 - app - INFO - Loaded feature names: ['Economy (GDP per Capita)', 'Family', 'Health (Life Expectancy)', 'Freedom', 'Trust (Government Corruption)', 'Generosity']
2024-11-18 12:54:07,257 - app - INFO - Starting application on port 5000
2024-11-18 12:54:53,587 - app - INFO - Input data shape: (1, 6)
2024-11-18 12:54:53,587 - app - INFO - Input features: ['Economy (GDP per Capita)', 'Family', 'Health (Life Expectancy)', 'Freedom', 'Trust (Government Corruption)', 'Generosity']
2024-11-18 12:54:53,599 - app - INFO - Prediction log: {'timestamp': '2024-11-18T12:54:53.599008', 'input_data': {'Economy (GDP per Capita)': 0.01, 'Family': 0.01, 'Health (Life Expectancy)': 0.01, 'Freedom': 0.01, 'Trust (Government Corruption)': 0.01, 'Generosity': 0.01}, 'prediction': 3.4381875138888893, 'success': True, 'error': None, 'client_ip': '127.0.0.1'}
2024-11-18 13:16:18,775 - app.app - INFO - Loading model artifacts...
2024-11-18 13:16:18,924 - app.app - ERROR - Error loading model artifacts: Can't get attribute 'PreprocessingPipeline' on <module '__main__' from '/usr/local/bin/gunicorn'>
Traceback (most recent call last):
  File "/app/app/app.py", line 68, in load_model_artifacts
    pipeline = PreprocessingPipeline.load(app.config['PIPELINE_PATH'])
  File "/app/src/preprocessing_pipeline.py", line 163, in load
    return joblib.load(path)
  File "/usr/local/lib/python3.9/site-packages/joblib/numpy_pickle.py", line 658, in load
    obj = _unpickle(fobj, filename, mmap_mode)
  File "/usr/local/lib/python3.9/site-packages/joblib/numpy_pickle.py", line 577, in _unpickle
    obj = unpickler.load()
  File "/usr/local/lib/python3.9/pickle.py", line 1212, in load
    dispatch[key[0]](self)
  File "/usr/local/lib/python3.9/pickle.py", line 1537, in load_stack_global
    self.append(self.find_class(module, name))
  File "/usr/local/lib/python3.9/pickle.py", line 1581, in find_class
    return _getattribute(sys.modules[module], name)[0]
  File "/usr/local/lib/python3.9/pickle.py", line 331, in _getattribute
    raise AttributeError("Can't get attribute {!r} on {!r}"
AttributeError: Can't get attribute 'PreprocessingPipeline' on <module '__main__' from '/usr/local/bin/gunicorn'>

2024-11-18 13:16:18,925 - app.app - ERROR - Failed to load model artifacts: Can't get attribute 'PreprocessingPipeline' on <module '__main__' from '/usr/local/bin/gunicorn'>
2024-11-18 13:21:38,135 - app.app - INFO - Loading model artifacts...
2024-11-18 13:21:38,149 - app.app - INFO - Loading model artifacts...
2024-11-18 13:21:38,195 - app.app - INFO - Loading model artifacts...
2024-11-18 13:21:38,394 - app.app - INFO - Loading model artifacts...
2024-11-18 13:21:38,582 - app.app - ERROR - Error loading model artifacts: Can't get attribute 'PreprocessingPipeline' on <module '__main__' from '/usr/local/bin/gunicorn'>
Traceback (most recent call last):
  File "/app/app/app.py", line 68, in load_model_artifacts
    pipeline = PreprocessingPipeline.load(app.config['PIPELINE_PATH'])
  File "/app/src/preprocessing_pipeline.py", line 163, in load
    return joblib.load(path)
  File "/usr/local/lib/python3.9/site-packages/joblib/numpy_pickle.py", line 658, in load
    obj = _unpickle(fobj, filename, mmap_mode)
  File "/usr/local/lib/python3.9/site-packages/joblib/numpy_pickle.py", line 577, in _unpickle
    obj = unpickler.load()
  File "/usr/local/lib/python3.9/pickle.py", line 1212, in load
    dispatch[key[0]](self)
  File "/usr/local/lib/python3.9/pickle.py", line 1537, in load_stack_global
    self.append(self.find_class(module, name))
  File "/usr/local/lib/python3.9/pickle.py", line 1581, in find_class
    return _getattribute(sys.modules[module], name)[0]
  File "/usr/local/lib/python3.9/pickle.py", line 331, in _getattribute
    raise AttributeError("Can't get attribute {!r} on {!r}"
AttributeError: Can't get attribute 'PreprocessingPipeline' on <module '__main__' from '/usr/local/bin/gunicorn'>

2024-11-18 13:21:38,590 - app.app - ERROR - Failed to load model artifacts: Can't get attribute 'PreprocessingPipeline' on <module '__main__' from '/usr/local/bin/gunicorn'>
2024-11-18 13:21:38,606 - app.app - ERROR - Error loading model artifacts: Can't get attribute 'PreprocessingPipeline' on <module '__main__' from '/usr/local/bin/gunicorn'>
Traceback (most recent call last):
  File "/app/app/app.py", line 68, in load_model_artifacts
    pipeline = PreprocessingPipeline.load(app.config['PIPELINE_PATH'])
  File "/app/src/preprocessing_pipeline.py", line 163, in load
    return joblib.load(path)
  File "/usr/local/lib/python3.9/site-packages/joblib/numpy_pickle.py", line 658, in load
    obj = _unpickle(fobj, filename, mmap_mode)
  File "/usr/local/lib/python3.9/site-packages/joblib/numpy_pickle.py", line 577, in _unpickle
    obj = unpickler.load()
  File "/usr/local/lib/python3.9/pickle.py", line 1212, in load
    dispatch[key[0]](self)
  File "/usr/local/lib/python3.9/pickle.py", line 1537, in load_stack_global
    self.append(self.find_class(module, name))
  File "/usr/local/lib/python3.9/pickle.py", line 1581, in find_class
    return _getattribute(sys.modules[module], name)[0]
  File "/usr/local/lib/python3.9/pickle.py", line 331, in _getattribute
    raise AttributeError("Can't get attribute {!r} on {!r}"
AttributeError: Can't get attribute 'PreprocessingPipeline' on <module '__main__' from '/usr/local/bin/gunicorn'>

2024-11-18 13:21:38,607 - app.app - ERROR - Failed to load model artifacts: Can't get attribute 'PreprocessingPipeline' on <module '__main__' from '/usr/local/bin/gunicorn'>
2024-11-18 13:21:38,635 - app.app - ERROR - Error loading model artifacts: Can't get attribute 'PreprocessingPipeline' on <module '__main__' from '/usr/local/bin/gunicorn'>
Traceback (most recent call last):
  File "/app/app/app.py", line 68, in load_model_artifacts
    pipeline = PreprocessingPipeline.load(app.config['PIPELINE_PATH'])
  File "/app/src/preprocessing_pipeline.py", line 163, in load
    return joblib.load(path)
  File "/usr/local/lib/python3.9/site-packages/joblib/numpy_pickle.py", line 658, in load
    obj = _unpickle(fobj, filename, mmap_mode)
  File "/usr/local/lib/python3.9/site-packages/joblib/numpy_pickle.py", line 577, in _unpickle
    obj = unpickler.load()
  File "/usr/local/lib/python3.9/pickle.py", line 1212, in load
    dispatch[key[0]](self)
  File "/usr/local/lib/python3.9/pickle.py", line 1537, in load_stack_global
    self.append(self.find_class(module, name))
  File "/usr/local/lib/python3.9/pickle.py", line 1581, in find_class
    return _getattribute(sys.modules[module], name)[0]
  File "/usr/local/lib/python3.9/pickle.py", line 331, in _getattribute
    raise AttributeError("Can't get attribute {!r} on {!r}"
AttributeError: Can't get attribute 'PreprocessingPipeline' on <module '__main__' from '/usr/local/bin/gunicorn'>

2024-11-18 13:21:38,635 - app.app - ERROR - Failed to load model artifacts: Can't get attribute 'PreprocessingPipeline' on <module '__main__' from '/usr/local/bin/gunicorn'>
2024-11-18 13:21:38,677 - app.app - ERROR - Error loading model artifacts: Can't get attribute 'PreprocessingPipeline' on <module '__main__' from '/usr/local/bin/gunicorn'>
Traceback (most recent call last):
  File "/app/app/app.py", line 68, in load_model_artifacts
    pipeline = PreprocessingPipeline.load(app.config['PIPELINE_PATH'])
  File "/app/src/preprocessing_pipeline.py", line 163, in load
    return joblib.load(path)
  File "/usr/local/lib/python3.9/site-packages/joblib/numpy_pickle.py", line 658, in load
    obj = _unpickle(fobj, filename, mmap_mode)
  File "/usr/local/lib/python3.9/site-packages/joblib/numpy_pickle.py", line 577, in _unpickle
    obj = unpickler.load()
  File "/usr/local/lib/python3.9/pickle.py", line 1212, in load
    dispatch[key[0]](self)
  File "/usr/local/lib/python3.9/pickle.py", line 1537, in load_stack_global
    self.append(self.find_class(module, name))
  File "/usr/local/lib/python3.9/pickle.py", line 1581, in find_class
    return _getattribute(sys.modules[module], name)[0]
  File "/usr/local/lib/python3.9/pickle.py", line 331, in _getattribute
    raise AttributeError("Can't get attribute {!r} on {!r}"
AttributeError: Can't get attribute 'PreprocessingPipeline' on <module '__main__' from '/usr/local/bin/gunicorn'>

2024-11-18 13:21:38,677 - app.app - ERROR - Failed to load model artifacts: Can't get attribute 'PreprocessingPipeline' on <module '__main__' from '/usr/local/bin/gunicorn'>
2024-11-18 13:29:31,351 - app - INFO - Loading model artifacts...
2024-11-18 13:29:31,651 - app - INFO - Model artifacts loaded successfully
2024-11-18 13:30:01,523 - app - INFO - Prediction log: {'timestamp': '2024-11-18T13:30:01.523093', 'input_data': {'Economy (GDP per Capita)': 0.01, 'Family': 0.01, 'Health (Life Expectancy)': 0.01, 'Freedom': 0.01, 'Trust (Government Corruption)': 0.01, 'Generosity': 0.01}, 'prediction': 3.4381875138888893, 'success': True, 'error': None, 'client_ip': '127.0.0.1'}
2024-11-18 13:37:21,847 - app.app - INFO - Loading model artifacts...
2024-11-18 13:37:22,033 - app.app - ERROR - Error loading model artifacts: Can't get attribute 'PreprocessingPipeline' on <module 'gunicorn.__main__' from '/usr/local/lib/python3.9/site-packages/gunicorn/__main__.py'>
Traceback (most recent call last):
  File "/app/app/app.py", line 56, in load_model_artifacts
    pipeline = PreprocessingPipeline.load(app.config['PIPELINE_PATH'])
  File "/app/app/../src/preprocessing_pipeline.py", line 163, in load
    return joblib.load(path)
  File "/usr/local/lib/python3.9/site-packages/joblib/numpy_pickle.py", line 658, in load
    obj = _unpickle(fobj, filename, mmap_mode)
  File "/usr/local/lib/python3.9/site-packages/joblib/numpy_pickle.py", line 577, in _unpickle
    obj = unpickler.load()
  File "/usr/local/lib/python3.9/pickle.py", line 1212, in load
    dispatch[key[0]](self)
  File "/usr/local/lib/python3.9/pickle.py", line 1537, in load_stack_global
    self.append(self.find_class(module, name))
  File "/usr/local/lib/python3.9/pickle.py", line 1581, in find_class
    return _getattribute(sys.modules[module], name)[0]
  File "/usr/local/lib/python3.9/pickle.py", line 331, in _getattribute
    raise AttributeError("Can't get attribute {!r} on {!r}"
AttributeError: Can't get attribute 'PreprocessingPipeline' on <module 'gunicorn.__main__' from '/usr/local/lib/python3.9/site-packages/gunicorn/__main__.py'>

2024-11-18 13:37:22,033 - app.app - ERROR - Failed to load model artifacts: Can't get attribute 'PreprocessingPipeline' on <module 'gunicorn.__main__' from '/usr/local/lib/python3.9/site-packages/gunicorn/__main__.py'>
2024-11-18 13:56:08,144 - app - INFO - Loading model artifacts...
2024-11-18 13:56:08,284 - app - INFO - Model artifacts loaded successfully
2024-11-18 13:56:38,118 - app - INFO - Prediction log: {'timestamp': '2024-11-18T13:56:38.118501', 'input_data': {'Economy (GDP per Capita)': 0.01, 'Family': 0.01, 'Health (Life Expectancy)': 0.01, 'Freedom': 0.01, 'Trust (Government Corruption)': 0.01, 'Generosity': 0.01}, 'prediction': 3.4381875138888893, 'success': True, 'error': None, 'client_ip': '127.0.0.1'}
2024-11-18 13:59:51,498 - app.app - INFO - Loading model artifacts...
2024-11-18 13:59:51,640 - app.app - ERROR - Error loading model artifacts: Can't get attribute 'PreprocessingPipeline' on <module 'gunicorn.__main__' from '/usr/local/lib/python3.9/site-packages/gunicorn/__main__.py'>
Traceback (most recent call last):
  File "/app/app/app.py", line 56, in load_model_artifacts
    pipeline = PreprocessingPipeline.load(app.config['PIPELINE_PATH'])
  File "/app/app/../src/preprocessing_pipeline.py", line 170, in load
    loaded_pipeline = joblib.load(path)
  File "/usr/local/lib/python3.9/site-packages/joblib/numpy_pickle.py", line 658, in load
    obj = _unpickle(fobj, filename, mmap_mode)
  File "/usr/local/lib/python3.9/site-packages/joblib/numpy_pickle.py", line 577, in _unpickle
    obj = unpickler.load()
  File "/usr/local/lib/python3.9/pickle.py", line 1212, in load
    dispatch[key[0]](self)
  File "/usr/local/lib/python3.9/pickle.py", line 1537, in load_stack_global
    self.append(self.find_class(module, name))
  File "/usr/local/lib/python3.9/pickle.py", line 1581, in find_class
    return _getattribute(sys.modules[module], name)[0]
  File "/usr/local/lib/python3.9/pickle.py", line 331, in _getattribute
    raise AttributeError("Can't get attribute {!r} on {!r}"
AttributeError: Can't get attribute 'PreprocessingPipeline' on <module 'gunicorn.__main__' from '/usr/local/lib/python3.9/site-packages/gunicorn/__main__.py'>

2024-11-18 13:59:51,641 - app.app - ERROR - Failed to load model artifacts: Can't get attribute 'PreprocessingPipeline' on <module 'gunicorn.__main__' from '/usr/local/lib/python3.9/site-packages/gunicorn/__main__.py'>
2024-11-18 14:07:55,756 - app.app - INFO - Loading model artifacts...
2024-11-18 14:07:55,897 - app.app - ERROR - Error loading model artifacts: Can't get attribute 'PreprocessingPipeline' on <module '__main__' from '/usr/local/bin/gunicorn'>
Traceback (most recent call last):
  File "/app/app/app.py", line 56, in load_model_artifacts
    pipeline = PreprocessingPipeline.load(app.config['PIPELINE_PATH'])
  File "/app/app/../src/preprocessing_pipeline.py", line 170, in load
    loaded_pipeline = joblib.load(path)
  File "/usr/local/lib/python3.9/site-packages/joblib/numpy_pickle.py", line 658, in load
    obj = _unpickle(fobj, filename, mmap_mode)
  File "/usr/local/lib/python3.9/site-packages/joblib/numpy_pickle.py", line 577, in _unpickle
    obj = unpickler.load()
  File "/usr/local/lib/python3.9/pickle.py", line 1212, in load
    dispatch[key[0]](self)
  File "/usr/local/lib/python3.9/pickle.py", line 1537, in load_stack_global
    self.append(self.find_class(module, name))
  File "/usr/local/lib/python3.9/pickle.py", line 1581, in find_class
    return _getattribute(sys.modules[module], name)[0]
  File "/usr/local/lib/python3.9/pickle.py", line 331, in _getattribute
    raise AttributeError("Can't get attribute {!r} on {!r}"
AttributeError: Can't get attribute 'PreprocessingPipeline' on <module '__main__' from '/usr/local/bin/gunicorn'>

2024-11-18 14:07:55,897 - app.app - ERROR - Failed to load model artifacts: Can't get attribute 'PreprocessingPipeline' on <module '__main__' from '/usr/local/bin/gunicorn'>
2024-11-18 14:09:43,539 - app.app - INFO - Loading model artifacts...
2024-11-18 14:09:43,676 - app.app - ERROR - Error loading model artifacts: Can't get attribute 'PreprocessingPipeline' on <module '__main__' from '/usr/local/bin/gunicorn'>
Traceback (most recent call last):
  File "/app/app/app.py", line 56, in load_model_artifacts
    pipeline = PreprocessingPipeline.load(app.config['PIPELINE_PATH'])
  File "/app/app/../src/preprocessing_pipeline.py", line 170, in load
    loaded_pipeline = joblib.load(path)
  File "/usr/local/lib/python3.9/site-packages/joblib/numpy_pickle.py", line 658, in load
    obj = _unpickle(fobj, filename, mmap_mode)
  File "/usr/local/lib/python3.9/site-packages/joblib/numpy_pickle.py", line 577, in _unpickle
    obj = unpickler.load()
  File "/usr/local/lib/python3.9/pickle.py", line 1212, in load
    dispatch[key[0]](self)
  File "/usr/local/lib/python3.9/pickle.py", line 1537, in load_stack_global
    self.append(self.find_class(module, name))
  File "/usr/local/lib/python3.9/pickle.py", line 1581, in find_class
    return _getattribute(sys.modules[module], name)[0]
  File "/usr/local/lib/python3.9/pickle.py", line 331, in _getattribute
    raise AttributeError("Can't get attribute {!r} on {!r}"
AttributeError: Can't get attribute 'PreprocessingPipeline' on <module '__main__' from '/usr/local/bin/gunicorn'>

2024-11-18 14:09:43,676 - app.app - ERROR - Failed to load model artifacts: Can't get attribute 'PreprocessingPipeline' on <module '__main__' from '/usr/local/bin/gunicorn'>
2024-11-18 14:14:00,265 - app.app - INFO - Loading model artifacts...
2024-11-18 14:14:00,401 - app.app - ERROR - Error loading model artifacts: Can't get attribute 'PreprocessingPipeline' on <module '__main__' from '/usr/local/bin/gunicorn'>
Traceback (most recent call last):
  File "/app/app/app.py", line 61, in load_model_artifacts
    pipeline = joblib.load(app.config['PIPELINE_PATH'])
  File "/usr/local/lib/python3.9/site-packages/joblib/numpy_pickle.py", line 658, in load
    obj = _unpickle(fobj, filename, mmap_mode)
  File "/usr/local/lib/python3.9/site-packages/joblib/numpy_pickle.py", line 577, in _unpickle
    obj = unpickler.load()
  File "/usr/local/lib/python3.9/pickle.py", line 1212, in load
    dispatch[key[0]](self)
  File "/usr/local/lib/python3.9/pickle.py", line 1537, in load_stack_global
    self.append(self.find_class(module, name))
  File "/usr/local/lib/python3.9/pickle.py", line 1581, in find_class
    return _getattribute(sys.modules[module], name)[0]
  File "/usr/local/lib/python3.9/pickle.py", line 331, in _getattribute
    raise AttributeError("Can't get attribute {!r} on {!r}"
AttributeError: Can't get attribute 'PreprocessingPipeline' on <module '__main__' from '/usr/local/bin/gunicorn'>

2024-11-18 14:14:00,401 - app.app - ERROR - Failed to load model artifacts: Can't get attribute 'PreprocessingPipeline' on <module '__main__' from '/usr/local/bin/gunicorn'>
2024-11-18 14:15:31,428 - app - INFO - Loading model artifacts...
2024-11-18 14:15:31,428 - app - ERROR - Error loading model artifacts: No module named 'src'
Traceback (most recent call last):
  File "/workspaces/happiness_prediction/app/app.py", line 57, in load_model_artifacts
    from src.preprocessing_pipeline import PreprocessingPipeline
ModuleNotFoundError: No module named 'src'

2024-11-18 14:15:31,429 - app - ERROR - Failed to load model artifacts: No module named 'src'
